Workbook

Sheet Picks importieren
C1: FFID | D1: 2 | F1: 3 | H1: 1
B2: SP_x | C2: 96.25 | D2: 1.7 | E2: 195 | F2: 1.6 | G2: -2.5 | H2: 1.8 | R2: T0 Korrektur | S2: 0
A3: Trace | B3: m | C3: x | D3: T zentral | E3: x | F3: T off-end - | G3: x | H3: T off-end + | I3: x | J3: T fern - | K3: x | L3: T fern + | M3: x | N3: T fern - - | O3: x | P3: T fern + + | R3: GEO_COMP | S3: 1
A4: 1 | B4: 0 | C4: =IF(C$2="","",SQRT(($B4-C$2)^2+D$2^2)) -> 96.265012 | D4: =SUMIFS(Tabelle1!$C$1:$C$1000,Tabelle1!$A$1:$A$1000,$A4+$S$4,Tabelle1!$B$1:$B$1000,D$1,Tabelle1!$D$1:$D$1000,$S$3) -> 69.4395 | E4: =IF(E$2="","",SQRT(($B4-E$2)^2+F$2^2)) -> 195.00656 | F4: =SUMIFS(Tabelle1!$C$1:$C$1000,Tabelle1!$A$1:$A$1000,$A4+$S$4,Tabelle1!$B$1:$B$1000,F$1,Tabelle1!$D$1:$D$1000,$S$3) -> 100.92 | G4: =IF(G$2="","",SQRT(($B4-G$2)^2+H$2^2)) -> 3.0805844 | H4: =SUMIFS(Tabelle1!$C$1:$C$1000,Tabelle1!$A$1:$A$1000,$A4+$S$4,Tabelle1!$B$1:$B$1000,H$1,Tabelle1!$D$1:$D$1000,$S$3) -> 7.90979 | I4: =IF(I$2="","",SQRT(($B4-I$2)^2+J$2^2)) | K4: =IF(K$2="","",SQRT(($B4-K$2)^2+L$2^2)) | M4: =IF(M$2="","",SQRT(($B4-M$2)^2+N$2^2)) | O4: =IF(O$2="","",SQRT(($B4-O$2)^2+P$2^2)) | R4: CHAN_OFFSET | S4: 0
A5: 2 | B5: 2.5 | C5: =IF(C$2="","",SQRT(($B5-C$2)^2+D$2^2)) -> 93.765412 | D5: =SUMIFS(Tabelle1!$C$1:$C$1000,Tabelle1!$A$1:$A$1000,$A5+$S$4,Tabelle1!$B$1:$B$1000,D$1,Tabelle1!$D$1:$D$1000,$S$3) -> 68.8263 | E5: =IF(E$2="","",SQRT(($B5-E$2)^2+F$2^2)) -> 192.50665 | F5: =SUMIFS(Tabelle1!$C$1:$C$1000,Tabelle1!$A$1:$A$1000,$A5+$S$4,Tabelle1!$B$1:$B$1000,F$1,Tabelle1!$D$1:$D$1000,$S$3) -> 100.511 | G5: =IF(G$2="","",SQRT(($B5-G$2)^2+H$2^2)) -> 5.3141321 | H5: =SUMIFS(Tabelle1!$C$1:$C$1000,Tabelle1!$A$1:$A$1000,$A5+$S$4,Tabelle1!$B$1:$B$1000,H$1,Tabelle1!$D$1:$D$1000,$S$3) -> 13.6335 | I5: =IF(I$2="","",SQRT(($B5-I$2)^2+J$2^2)) | K5: =IF(K$2="","",SQRT(($B5-K$2)^2+L$2^2)) | M5: =IF(M$2="","",SQRT(($B5-M$2)^2+N$2^2)) | O5: =IF(O$2="","",SQRT(($B5-O$2)^2+P$2^2))
A6: 3 | B6: 5 | C6: =IF(C$2="","",SQRT(($B6-C$2)^2+D$2^2)) -> 91.265834 | D6: =SUMIFS(Tabelle1!$C$1:$C$1000,Tabelle1!$A$1:$A$1000,$A6+$S$4,Tabelle1!$B$1:$B$1000,D$1,Tabelle1!$D$1:$D$1000,$S$3) -> 68.0086 | E6: =IF(E$2="","",SQRT(($B6-E$2)^2+F$2^2)) -> 190.00674 | F6: =SUMIFS(Tabelle1!$C$1:$C$1000,Tabelle1!$A$1:$A$1000,$A6+$S$4,Tabelle1!$B$1:$B$1000,F$1,Tabelle1!$D$1:$D$1000,$S$3) -> 100.102 | G6: =IF(G$2="","",SQRT(($B6-G$2)^2+H$2^2)) -> 7.7129761 | H6: =SUMIFS(Tabelle1!$C$1:$C$1000,Tabelle1!$A$1:$A$1000,$A6+$S$4,Tabelle1!$B$1:$B$1000,H$1,Tabelle1!$D$1:$D$1000,$S$3) -> 18.5032 | I6: =IF(I$2="","",SQRT(($B6-I$2)^2+J$2^2)) | K6: =IF(K$2="","",SQRT(($B6-K$2)^2+L$2^2)) | M6: =IF(M$2="","",SQRT(($B6-M$2)^2+N$2^2)) | O6: =IF(O$2="","",SQRT(($B6-O$2)^2+P$2^2))
A7: 4 | B7: 7.5 | C7: =IF(C$2="","",SQRT(($B7-C$2)^2+D$2^2)) -> 88.76628 | D7: =SUMIFS(Tabelle1!$C$1:$C$1000,Tabelle1!$A$1:$A$1000,$A7+$S$4,Tabelle1!$B$1:$B$1000,D$1,Tabelle1!$D$1:$D$1000,$S$3) -> 67.1909 | E7: =IF(E$2="","",SQRT(($B7-E$2)^2+F$2^2)) -> 187.50683 | F7: =SUMIFS(Tabelle1!$C$1:$C$1000,Tabelle1!$A$1:$A$1000,$A7+$S$4,Tabelle1!$B$1:$B$1000,F$1,Tabelle1!$D$1:$D$1000,$S$3) -> 99.2845 | G7: =IF(G$2="","",SQRT(($B7-G$2)^2+H$2^2)) -> 10.160709 | H7: =SUMIFS(Tabelle1!$C$1:$C$1000,Tabelle1!$A$1:$A$1000,$A7+$S$4,Tabelle1!$B$1:$B$1000,H$1,Tabelle1!$D$1:$D$1000,$S$3) -> 23.6247 | I7: =IF(I$2="","",SQRT(($B7-I$2)^2+J$2^2)) | K7: =IF(K$2="","",SQRT(($B7-K$2)^2+L$2^2)) | M7: =IF(M$2="","",SQRT(($B7-M$2)^2+N$2^2)) | O7: =IF(O$2="","",SQRT(($B7-O$2)^2+P$2^2))
A8: 5 | B8: 10 | C8: =IF(C$2="","",SQRT(($B8-C$2)^2+D$2^2)) -> 86.266752 | D8: =SUMIFS(Tabelle1!$C$1:$C$1000,Tabelle1!$A$1:$A$1000,$A8+$S$4,Tabelle1!$B$1:$B$1000,D$1,Tabelle1!$D$1:$D$1000,$S$3) -> 66.3733 | E8: =IF(E$2="","",SQRT(($B8-E$2)^2+F$2^2)) -> 185.00692 | F8: =SUMIFS(Tabelle1!$C$1:$C$1000,Tabelle1!$A$1:$A$1000,$A8+$S$4,Tabelle1!$B$1:$B$1000,F$1,Tabelle1!$D$1:$D$1000,$S$3) -> 98.4669 | G8: =IF(G$2="","",SQRT(($B8-G$2)^2+H$2^2)) -> 12.628935 | H8: =SUMIFS(Tabelle1!$C$1:$C$1000,Tabelle1!$A$1:$A$1000,$A8+$S$4,Tabelle1!$B$1:$B$1000,H$1,Tabelle1!$D$1:$D$1000,$S$3) -> 28.8743 | I8: =IF(I$2="","",SQRT(($B8-I$2)^2+J$2^2)) | K8: =IF(K$2="","",SQRT(($B8-K$2)^2+L$2^2)) | M8: =IF(M$2="","",SQRT(($B8-M$2)^2+N$2^2)) | O8: =IF(O$2="","",SQRT(($B8-O$2)^2+P$2^2))
A9: 6 | B9: 15 | C9: =IF(C$2="","",SQRT(($B9-C$2)^2+D$2^2)) -> 81.267783 | D9: =SUMIFS(Tabelle1!$C$1:$C$1000,Tabelle1!$A$1:$A$1000,$A9+$S$4,Tabelle1!$B$1:$B$1000,D$1,Tabelle1!$D$1:$D$1000,$S$3) -> 63.7158 | E9: =IF(E$2="","",SQRT(($B9-E$2)^2+F$2^2)) -> 180.00711 | F9: =SUMIFS(Tabelle1!$C$1:$C$1000,Tabelle1!$A$1:$A$1000,$A9+$S$4,Tabelle1!$B$1:$B$1000,F$1,Tabelle1!$D$1:$D$1000,$S$3) -> 97.0359 | G9: =IF(G$2="","",SQRT(($B9-G$2)^2+H$2^2)) -> 17.592328 | H9: =SUMIFS(Tabelle1!$C$1:$C$1000,Tabelle1!$A$1:$A$1000,$A9+$S$4,Tabelle1!$B$1:$B$1000,H$1,Tabelle1!$D$1:$D$1000,$S$3) -> 32.7155 | I9: =IF(I$2="","",SQRT(($B9-I$2)^2+J$2^2)) | K9: =IF(K$2="","",SQRT(($B9-K$2)^2+L$2^2)) | M9: =IF(M$2="","",SQRT(($B9-M$2)^2+N$2^2)) | O9: =IF(O$2="","",SQRT(($B9-O$2)^2+P$2^2))
A10: 7 | B10: 20 | C10: =IF(C$2="","",SQRT(($B10-C$2)^2+D$2^2)) -> 76.268948 | D10: =SUMIFS(Tabelle1!$C$1:$C$1000,Tabelle1!$A$1:$A$1000,$A10+$S$4,Tabelle1!$B$1:$B$1000,D$1,Tabelle1!$D$1:$D$1000,$S$3) -> 61.8761 | E10: =IF(E$2="","",SQRT(($B10-E$2)^2+F$2^2)) -> 175.00731 | F10: =SUMIFS(Tabelle1!$C$1:$C$1000,Tabelle1!$A$1:$A$1000,$A10+$S$4,Tabelle1!$B$1:$B$1000,F$1,Tabelle1!$D$1:$D$1000,$S$3) -> 95.605 | G10: =IF(G$2="","",SQRT(($B10-G$2)^2+H$2^2)) -> 22.571885 | H10: =SUMIFS(Tabelle1!$C$1:$C$1000,Tabelle1!$A$1:$A$1000,$A10+$S$4,Tabelle1!$B$1:$B$1000,H$1,Tabelle1!$D$1:$D$1000,$S$3) -> 35.7884 | I10: =IF(I$2="","",SQRT(($B10-I$2)^2+J$2^2)) | K10: =IF(K$2="","",SQRT(($B10-K$2)^2+L$2^2)) | M10: =IF(M$2="","",SQRT(($B10-M$2)^2+N$2^2)) | O10: =IF(O$2="","",SQRT(($B10-O$2)^2+P$2^2))
A11: 8 | B11: 25 | C11: =IF(C$2="","",SQRT(($B11-C$2)^2+D$2^2)) -> 71.270278 | D11: =SUMIFS(Tabelle1!$C$1:$C$1000,Tabelle1!$A$1:$A$1000,$A11+$S$4,Tabelle1!$B$1:$B$1000,D$1,Tabelle1!$D$1:$D$1000,$S$3) -> 59.8319 | E11: =IF(E$2="","",SQRT(($B11-E$2)^2+F$2^2)) -> 170.00753 | F11: =SUMIFS(Tabelle1!$C$1:$C$1000,Tabelle1!$A$1:$A$1000,$A11+$S$4,Tabelle1!$B$1:$B$1000,F$1,Tabelle1!$D$1:$D$1000,$S$3) -> 94.3785 | G11: =IF(G$2="","",SQRT(($B11-G$2)^2+H$2^2)) -> 27.558846 | H11: =SUMIFS(Tabelle1!$C$1:$C$1000,Tabelle1!$A$1:$A$1000,$A11+$S$4,Tabelle1!$B$1:$B$1000,H$1,Tabelle1!$D$1:$D$1000,$S$3) -> 38.368 | I11: =IF(I$2="","",SQRT(($B11-I$2)^2+J$2^2)) | K11: =IF(K$2="","",SQRT(($B11-K$2)^2+L$2^2)) | M11: =IF(M$2="","",SQRT(($B11-M$2)^2+N$2^2)) | O11: =IF(O$2="","",SQRT(($B11-O$2)^2+P$2^2))
A12: 9 | B12: 30 | C12: =IF(C$2="","",SQRT(($B12-C$2)^2+D$2^2)) -> 66.271808 | D12: =SUMIFS(Tabelle1!$C$1:$C$1000,Tabelle1!$A$1:$A$1000,$A12+$S$4,Tabelle1!$B$1:$B$1000,D$1,Tabelle1!$D$1:$D$1000,$S$3) -> 57.1745 | E12: =IF(E$2="","",SQRT(($B12-E$2)^2+F$2^2)) -> 165.00776 | F12: =SUMIFS(Tabelle1!$C$1:$C$1000,Tabelle1!$A$1:$A$1000,$A12+$S$4,Tabelle1!$B$1:$B$1000,F$1,Tabelle1!$D$1:$D$1000,$S$3) -> 92.5387 | G12: =IF(G$2="","",SQRT(($B12-G$2)^2+H$2^2)) -> 32.549808 | H12: =SUMIFS(Tabelle1!$C$1:$C$1000,Tabelle1!$A$1:$A$1000,$A12+$S$4,Tabelle1!$B$1:$B$1000,H$1,Tabelle1!$D$1:$D$1000,$S$3) -> 41.1661 | I12: =IF(I$2="","",SQRT(($B12-I$2)^2+J$2^2)) | K12: =IF(K$2="","",SQRT(($B12-K$2)^2+L$2^2)) | M12: =IF(M$2="","",SQRT(($B12-M$2)^2+N$2^2)) | O12: =IF(O$2="","",SQRT(($B12-O$2)^2+P$2^2))
A13: 10 | B13: 35 | C13: =IF(C$2="","",SQRT(($B13-C$2)^2+D$2^2)) -> 61.273587 | D13: =SUMIFS(Tabelle1!$C$1:$C$1000,Tabelle1!$A$1:$A$1000,$A13+$S$4,Tabelle1!$B$1:$B$1000,D$1,Tabelle1!$D$1:$D$1000,$S$3) -> 54.517 | E13: =IF(E$2="","",SQRT(($B13-E$2)^2+F$2^2)) -> 160.008 | F13: =SUMIFS(Tabelle1!$C$1:$C$1000,Tabelle1!$A$1:$A$1000,$A13+$S$4,Tabelle1!$B$1:$B$1000,F$1,Tabelle1!$D$1:$D$1000,$S$3) -> 90.4946 | G13: =IF(G$2="","",SQRT(($B13-G$2)^2+H$2^2)) -> 37.543175 | H13: =SUMIFS(Tabelle1!$C$1:$C$1000,Tabelle1!$A$1:$A$1000,$A13+$S$4,Tabelle1!$B$1:$B$1000,H$1,Tabelle1!$D$1:$D$1000,$S$3) -> 43.7268 | I13: =IF(I$2="","",SQRT(($B13-I$2)^2+J$2^2)) | K13: =IF(K$2="","",SQRT(($B13-K$2)^2+L$2^2)) | M13: =IF(M$2="","",SQRT(($B13-M$2)^2+N$2^2)) | O13: =IF(O$2="","",SQRT(($B13-O$2)^2+P$2^2))
A14: 11 | B14: 40 | C14: =IF(C$2="","",SQRT(($B14-C$2)^2+D$2^2)) -> 56.275683 | D14: =SUMIFS(Tabelle1!$C$1:$C$1000,Tabelle1!$A$1:$A$1000,$A14+$S$4,Tabelle1!$B$1:$B$1000,D$1,Tabelle1!$D$1:$D$1000,$S$3) -> 51.2464 | E14: =IF(E$2="","",SQRT(($B14-E$2)^2+F$2^2)) -> 155.00826 | F14: =SUMIFS(Tabelle1!$C$1:$C$1000,Tabelle1!$A$1:$A$1000,$A14+$S$4,Tabelle1!$B$1:$B$1000,F$1,Tabelle1!$D$1:$D$1000,$S$3) -> 88.8592 | G14: =IF(G$2="","",SQRT(($B14-G$2)^2+H$2^2)) -> 42.538101 | H14: =SUMIFS(Tabelle1!$C$1:$C$1000,Tabelle1!$A$1:$A$1000,$A14+$S$4,Tabelle1!$B$1:$B$1000,H$1,Tabelle1!$D$1:$D$1000,$S$3) -> 46.2876 | I14: =IF(I$2="","",SQRT(($B14-I$2)^2+J$2^2)) | K14: =IF(K$2="","",SQRT(($B14-K$2)^2+L$2^2)) | M14: =IF(M$2="","",SQRT(($B14-M$2)^2+N$2^2)) | O14: =IF(O$2="","",SQRT(($B14-O$2)^2+P$2^2))
A15: 12 | B15: 45 | C15: =IF(C$2="","",SQRT(($B15-C$2)^2+D$2^2)) -> 51.278187 | D15: =SUMIFS(Tabelle1!$C$1:$C$1000,Tabelle1!$A$1:$A$1000,$A15+$S$4,Tabelle1!$B$1:$B$1000,D$1,Tabelle1!$D$1:$D$1000,$S$3) -> 48.7934 | E15: =IF(E$2="","",SQRT(($B15-E$2)^2+F$2^2)) -> 150.00853 | F15: =SUMIFS(Tabelle1!$C$1:$C$1000,Tabelle1!$A$1:$A$1000,$A15+$S$4,Tabelle1!$B$1:$B$1000,F$1,Tabelle1!$D$1:$D$1000,$S$3) -> 87.2239 | G15: =IF(G$2="","",SQRT(($B15-G$2)^2+H$2^2)) -> 47.534093 | H15: =SUMIFS(Tabelle1!$C$1:$C$1000,Tabelle1!$A$1:$A$1000,$A15+$S$4,Tabelle1!$B$1:$B$1000,H$1,Tabelle1!$D$1:$D$1000,$S$3) -> 49.1045 | I15: =IF(I$2="","",SQRT(($B15-I$2)^2+J$2^2)) | K15: =IF(K$2="","",SQRT(($B15-K$2)^2+L$2^2)) | M15: =IF(M$2="","",SQRT(($B15-M$2)^2+N$2^2)) | O15: =IF(O$2="","",SQRT(($B15-O$2)^2+P$2^2))
A16: 13 | B16: 50 | C16: =IF(C$2="","",SQRT(($B16-C$2)^2+D$2^2)) -> 46.281233 | D16: =SUMIFS(Tabelle1!$C$1:$C$1000,Tabelle1!$A$1:$A$1000,$A16+$S$4,Tabelle1!$B$1:$B$1000,D$1,Tabelle1!$D$1:$D$1000,$S$3) -> 46.1359 | E16: =IF(E$2="","",SQRT(($B16-E$2)^2+F$2^2)) -> 145.00883 | F16: =SUMIFS(Tabelle1!$C$1:$C$1000,Tabelle1!$A$1:$A$1000,$A16+$S$4,Tabelle1!$B$1:$B$1000,F$1,Tabelle1!$D$1:$D$1000,$S$3) -> 85.5885 | G16: =IF(G$2="","",SQRT(($B16-G$2)^2+H$2^2)) -> 52.530848 | H16: =SUMIFS(Tabelle1!$C$1:$C$1000,Tabelle1!$A$1:$A$1000,$A16+$S$4,Tabelle1!$B$1:$B$1000,H$1,Tabelle1!$D$1:$D$1000,$S$3) -> 51.9213 | I16: =IF(I$2="","",SQRT(($B16-I$2)^2+J$2^2)) | K16: =IF(K$2="","",SQRT(($B16-K$2)^2+L$2^2)) | M16: =IF(M$2="","",SQRT(($B16-M$2)^2+N$2^2)) | O16: =IF(O$2="","",SQRT(($B16-O$2)^2+P$2^2))
... A51: 48 | B51: 192.5 | C51: =IF(C$2="","",SQRT(($B51-C$2)^2+D$2^2)) -> 96.265012 | D51: =SUMIFS(Tabelle1!$C$1:$C$1000,Tabelle1!$A$1:$A$1000,$A51+$S$4,Tabelle1!$B$1:$B$1000,D$1,Tabelle1!$D$1:$D$1000,$S$3) -> 70.6661 | E51: =IF(E$2="","",SQRT(($B51-E$2)^2+F$2^2)) -> 2.9681644 | F51: =SUMIFS(Tabelle1!$C$1:$C$1000,Tabelle1!$A$1:$A$1000,$A51+$S$4,Tabelle1!$B$1:$B$1000,F$1,Tabelle1!$D$1:$D$1000,$S$3) -> 5.45678 | G51: =IF(G$2="","",SQRT(($B51-G$2)^2+H$2^2)) -> 195.00831 | H51: =SUMIFS(Tabelle1!$C$1:$C$1000,Tabelle1!$A$1:$A$1000,$A51+$S$4,Tabelle1!$B$1:$B$1000,H$1,Tabelle1!$D$1:$D$1000,$S$3) -> 99.8079 | I51: =IF(I$2="","",SQRT(($B51-I$2)^2+J$2^2)) | K51: =IF(K$2="","",SQRT(($B51-K$2)^2+L$2^2)) | M51: =IF(M$2="","",SQRT(($B51-M$2)^2+N$2^2)) | O51: =IF(O$2="","",SQRT(($B51-O$2)^2+P$2^2))
I52: =IF(I$2="","",SQRT(($B52-I$2)^2+J$2^2)) | K52: =IF(K$2="","",SQRT(($B52-K$2)^2+L$2^2)) | M52: =IF(M$2="","",SQRT(($B52-M$2)^2+N$2^2)) | O52: =IF(O$2="","",SQRT(($B52-O$2)^2+P$2^2))
I53: =IF(I$2="","",SQRT(($B53-I$2)^2+J$2^2)) | K53: =IF(K$2="","",SQRT(($B53-K$2)^2+L$2^2)) | M53: =IF(M$2="","",SQRT(($B53-M$2)^2+N$2^2)) | O53: =IF(O$2="","",SQRT(($B53-O$2)^2+P$2^2))
I54: =IF(I$2="","",SQRT(($B54-I$2)^2+J$2^2)) | K54: =IF(K$2="","",SQRT(($B54-K$2)^2+L$2^2)) | M54: =IF(M$2="","",SQRT(($B54-M$2)^2+N$2^2)) | O54: =IF(O$2="","",SQRT(($B54-O$2)^2+P$2^2))
I55: =IF(I$2="","",SQRT(($B55-I$2)^2+J$2^2)) | K55: =IF(K$2="","",SQRT(($B55-K$2)^2+L$2^2)) | M55: =IF(M$2="","",SQRT(($B55-M$2)^2+N$2^2)) | O55: =IF(O$2="","",SQRT(($B55-O$2)^2+P$2^2))
I56: =IF(I$2="","",SQRT(($B56-I$2)^2+J$2^2)) | K56: =IF(K$2="","",SQRT(($B56-K$2)^2+L$2^2)) | M56: =IF(M$2="","",SQRT(($B56-M$2)^2+N$2^2)) | O56: =IF(O$2="","",SQRT(($B56-O$2)^2+P$2^2))
I57: =IF(I$2="","",SQRT(($B57-I$2)^2+J$2^2)) | K57: =IF(K$2="","",SQRT(($B57-K$2)^2+L$2^2)) | M57: =IF(M$2="","",SQRT(($B57-M$2)^2+N$2^2)) | O57: =IF(O$2="","",SQRT(($B57-O$2)^2+P$2^2))
B60: WEITER

Sheet T0_Korrektur
B1: SP_x | C1: =IF('Picks importieren'!C2="","",'Picks importieren'!C2) -> 96.25 | D1: =IF('Picks importieren'!D2="","",'Picks importieren'!D2) -> 1.7 | E1: =IF('Picks importieren'!E2="","",'Picks importieren'!E2) -> 195 | F1: =IF('Picks importieren'!F2="","",'Picks importieren'!F2) -> 1.6 | G1: =IF('Picks importieren'!G2="","",'Picks importieren'!G2) -> -2.5 | H1: =IF('Picks importieren'!H2="","",'Picks importieren'!H2) -> 1.8 | I1: =IF('Picks importieren'!I2="","",'Picks importieren'!I2) | J1: =IF('Picks importieren'!J2="","",'Picks importieren'!J2) | ... P1: =IF('Picks importieren'!P2="","",'Picks importieren'!P2)
A2: Trace | B2: m | C2: x | D2: T zentral | E2: x | F2: T off-end - | G2: x | H2: T off-end + | I2: x | J2: T fern - | K2: x | L2: T fern + | M2: x | N2: T fern - - | O2: x | P2: T fern + +
A3: 1 | B3: ='Picks importieren'!B4 -> 0 | C3: =IF(C$1="","",SQRT(($B3-C$1)^2+D$1^2)) -> 96.265012 | D3: ='Picks importieren'!D4+'Picks importieren'!$S$2 -> 69.4395 | E3: =IF(E$1="","",SQRT(($B3-E$1)^2+F$1^2)) -> 195.00656 | F3: ='Picks importieren'!F4+'Picks importieren'!$S$2 -> 100.92 | G3: =IF(G$1="","",SQRT(($B3-G$1)^2+H$1^2)) -> 3.0805844 | H3: ='Picks importieren'!H4+'Picks importieren'!$S$2 -> 7.90979 | I3: =IF(I$1="",-999,SQRT(($B3-I$1)^2+J$1^2)) -> -999 | J3: =IF('Picks importieren'!J4="",-999,'Picks importieren'!J4+'Picks importieren'!$S$2) -> -999 | K3: =IF(K$1="",-999,SQRT(($B3-K$1)^2+L$1^2)) -> -999 | L3: =IF('Picks importieren'!L4="",-999,'Picks importieren'!L4+'Picks importieren'!$S$2) -> -999 | M3: =IF(M$1="",-999,SQRT(($B3-M$1)^2+N$1^2)) -> -999 | N3: =IF('Picks importieren'!N4="",-999,'Picks importieren'!N4+'Picks importieren'!$S$2) -> -999 | O3: =IF(O$1="",-999,SQRT(($B3-O$1)^2+P$1^2)) -> -999 | P3: =IF('Picks importieren'!P4="",-999,'Picks importieren'!P4+'Picks importieren'!$S$2) -> -999
A4: 2 | B4: ='Picks importieren'!B5 -> 2.5 | C4: =IF(C$1="","",SQRT(($B4-C$1)^2+D$1^2)) -> 93.765412 | D4: ='Picks importieren'!D5+'Picks importieren'!$S$2 -> 68.8263 | E4: =IF(E$1="","",SQRT(($B4-E$1)^2+F$1^2)) -> 192.50665 | F4: ='Picks importieren'!F5+'Picks importieren'!$S$2 -> 100.511 | G4: =IF(G$1="","",SQRT(($B4-G$1)^2+H$1^2)) -> 5.3141321 | H4: ='Picks importieren'!H5+'Picks importieren'!$S$2 -> 13.6335 | I4: =IF(I$1="",-999,SQRT(($B4-I$1)^2+J$1^2)) -> -999 | J4: =IF('Picks importieren'!J5="",-999,'Picks importieren'!J5+'Picks importieren'!$S$2) -> -999 | K4: =IF(K$1="",-999,SQRT(($B4-K$1)^2+L$1^2)) -> -999 | L4: =IF('Picks importieren'!L5="",-999,'Picks importieren'!L5+'Picks importieren'!$S$2) -> -999 | M4: =IF(M$1="",-999,SQRT(($B4-M$1)^2+N$1^2)) -> -999 | N4: =IF('Picks importieren'!N5="",-999,'Picks importieren'!N5+'Picks importieren'!$S$2) -> -999 | O4: =IF(O$1="",-999,SQRT(($B4-O$1)^2+P$1^2)) -> -999 | P4: =IF('Picks importieren'!P5="",-999,'Picks importieren'!P5+'Picks importieren'!$S$2) -> -999
A5: 3 | B5: ='Picks importieren'!B6 -> 5 | C5: =IF(C$1="","",SQRT(($B5-C$1)^2+D$1^2)) -> 91.265834 | D5: ='Picks importieren'!D6+'Picks importieren'!$S$2 -> 68.0086 | E5: =IF(E$1="","",SQRT(($B5-E$1)^2+F$1^2)) -> 190.00674 | F5: ='Picks importieren'!F6+'Picks importieren'!$S$2 -> 100.102 | G5: =IF(G$1="","",SQRT(($B5-G$1)^2+H$1^2)) -> 7.7129761 | H5: ='Picks importieren'!H6+'Picks importieren'!$S$2 -> 18.5032 | I5: =IF(I$1="",-999,SQRT(($B5-I$1)^2+J$1^2)) -> -999 | J5: =IF('Picks importieren'!J6="",-999,'Picks importieren'!J6+'Picks importieren'!$S$2) -> -999 | K5: =IF(K$1="",-999,SQRT(($B5-K$1)^2+L$1^2)) -> -999 | L5: =IF('Picks importieren'!L6="",-999,'Picks importieren'!L6+'Picks importieren'!$S$2) -> -999 | M5: =IF(M$1="",-999,SQRT(($B5-M$1)^2+N$1^2)) -> -999 | N5: =IF('Picks importieren'!N6="",-999,'Picks importieren'!N6+'Picks importieren'!$S$2) -> -999 | O5: =IF(O$1="",-999,SQRT(($B5-O$1)^2+P$1^2)) -> -999 | P5: =IF('Picks importieren'!P6="",-999,'Picks importieren'!P6+'Picks importieren'!$S$2) -> -999
A6: 4 | B6: ='Picks importieren'!B7 -> 7.5 | C6: =IF(C$1="","",SQRT(($B6-C$1)^2+D$1^2)) -> 88.76628 | D6: ='Picks importieren'!D7+'Picks importieren'!$S$2 -> 67.1909 | E6: =IF(E$1="","",SQRT(($B6-E$1)^2+F$1^2)) -> 187.50683 | F6: ='Picks importieren'!F7+'Picks importieren'!$S$2 -> 99.2845 | G6: =IF(G$1="","",SQRT(($B6-G$1)^2+H$1^2)) -> 10.160709 | H6: ='Picks importieren'!H7+'Picks importieren'!$S$2 -> 23.6247 | I6: =IF(I$1="",-999,SQRT(($B6-I$1)^2+J$1^2)) -> -999 | J6: =IF('Picks importieren'!J7="",-999,'Picks importieren'!J7+'Picks importieren'!$S$2) -> -999 | K6: =IF(K$1="",-999,SQRT(($B6-K$1)^2+L$1^2)) -> -999 | L6: =IF('Picks importieren'!L7="",-999,'Picks importieren'!L7+'Picks importieren'!$S$2) -> -999 | M6: =IF(M$1="",-999,SQRT(($B6-M$1)^2+N$1^2)) -> -999 | N6: =IF('Picks importieren'!N7="",-999,'Picks importieren'!N7+'Picks importieren'!$S$2) -> -999 | O6: =IF(O$1="",-999,SQRT(($B6-O$1)^2+P$1^2)) -> -999 | P6: =IF('Picks importieren'!P7="",-999,'Picks importieren'!P7+'Picks importieren'!$S$2) -> -999
A7: 5 | B7: ='Picks importieren'!B8 -> 10 | C7: =IF(C$1="","",SQRT(($B7-C$1)^2+D$1^2)) -> 86.266752 | D7: ='Picks importieren'!D8+'Picks importieren'!$S$2 -> 66.3733 | E7: =IF(E$1="","",SQRT(($B7-E$1)^2+F$1^2)) -> 185.00692 | F7: ='Picks importieren'!F8+'Picks importieren'!$S$2 -> 98.4669 | G7: =IF(G$1="","",SQRT(($B7-G$1)^2+H$1^2)) -> 12.628935 | H7: ='Picks importieren'!H8+'Picks importieren'!$S$2 -> 28.8743 | I7: =IF(I$1="",-999,SQRT(($B7-I$1)^2+J$1^2)) -> -999 | J7: =IF('Picks importieren'!J8="",-999,'Picks importieren'!J8+'Picks importieren'!$S$2) -> -999 | K7: =IF(K$1="",-999,SQRT(($B7-K$1)^2+L$1^2)) -> -999 | L7: =IF('Picks importieren'!L8="",-999,'Picks importieren'!L8+'Picks importieren'!$S$2) -> -999 | M7: =IF(M$1="",-999,SQRT(($B7-M$1)^2+N$1^2)) -> -999 | N7: =IF('Picks importieren'!N8="",-999,'Picks importieren'!N8+'Picks importieren'!$S$2) -> -999 | O7: =IF(O$1="",-999,SQRT(($B7-O$1)^2+P$1^2)) -> -999 | P7: =IF('Picks importieren'!P8="",-999,'Picks importieren'!P8+'Picks importieren'!$S$2) -> -999
A8: 6 | B8: ='Picks importieren'!B9 -> 15 | C8: =IF(C$1="","",SQRT(($B8-C$1)^2+D$1^2)) -> 81.267783 | D8: ='Picks importieren'!D9+'Picks importieren'!$S$2 -> 63.7158 | E8: =IF(E$1="","",SQRT(($B8-E$1)^2+F$1^2)) -> 180.00711 | F8: ='Picks importieren'!F9+'Picks importieren'!$S$2 -> 97.0359 | G8: =IF(G$1="","",SQRT(($B8-G$1)^2+H$1^2)) -> 17.592328 | H8: ='Picks importieren'!H9+'Picks importieren'!$S$2 -> 32.7155 | I8: =IF(I$1="",-999,SQRT(($B8-I$1)^2+J$1^2)) -> -999 | J8: =IF('Picks importieren'!J9="",-999,'Picks importieren'!J9+'Picks importieren'!$S$2) -> -999 | K8: =IF(K$1="",-999,SQRT(($B8-K$1)^2+L$1^2)) -> -999 | L8: =IF('Picks importieren'!L9="",-999,'Picks importieren'!L9+'Picks importieren'!$S$2) -> -999 | M8: =IF(M$1="",-999,SQRT(($B8-M$1)^2+N$1^2)) -> -999 | N8: =IF('Picks importieren'!N9="",-999,'Picks importieren'!N9+'Picks importieren'!$S$2) -> -999 | O8: =IF(O$1="",-999,SQRT(($B8-O$1)^2+P$1^2)) -> -999 | P8: =IF('Picks importieren'!P9="",-999,'Picks importieren'!P9+'Picks importieren'!$S$2) -> -999
A9: 7 | B9: ='Picks importieren'!B10 -> 20 | C9: =IF(C$1="","",SQRT(($B9-C$1)^2+D$1^2)) -> 76.268948 | D9: ='Picks importieren'!D10+'Picks importieren'!$S$2 -> 61.8761 | E9: =IF(E$1="","",SQRT(($B9-E$1)^2+F$1^2)) -> 175.00731 | F9: ='Picks importieren'!F10+'Picks importieren'!$S$2 -> 95.605 | G9: =IF(G$1="","",SQRT(($B9-G$1)^2+H$1^2)) -> 22.571885 | H9: ='Picks importieren'!H10+'Picks importieren'!$S$2 -> 35.7884 | I9: =IF(I$1="",-999,SQRT(($B9-I$1)^2+J$1^2)) -> -999 | J9: =IF('Picks importieren'!J10="",-999,'Picks importieren'!J10+'Picks importieren'!$S$2) -> -999 | K9: =IF(K$1="",-999,SQRT(($B9-K$1)^2+L$1^2)) -> -999 | L9: =IF('Picks importieren'!L10="",-999,'Picks importieren'!L10+'Picks importieren'!$S$2) -> -999 | M9: =IF(M$1="",-999,SQRT(($B9-M$1)^2+N$1^2)) -> -999 | N9: =IF('Picks importieren'!N10="",-999,'Picks importieren'!N10+'Picks importieren'!$S$2) -> -999 | O9: =IF(O$1="",-999,SQRT(($B9-O$1)^2+P$1^2)) -> -999 | P9: =IF('Picks importieren'!P10="",-999,'Picks importieren'!P10+'Picks importieren'!$S$2) -> -999
A10: 8 | B10: ='Picks importieren'!B11 -> 25 | C10: =IF(C$1="","",SQRT(($B10-C$1)^2+D$1^2)) -> 71.270278 | D10: ='Picks importieren'!D11+'Picks importieren'!$S$2 -> 59.8319 | E10: =IF(E$1="","",SQRT(($B10-E$1)^2+F$1^2)) -> 170.00753 | F10: ='Picks importieren'!F11+'Picks importieren'!$S$2 -> 94.3785 | G10: =IF(G$1="","",SQRT(($B10-G$1)^2+H$1^2)) -> 27.558846 | H10: ='Picks importieren'!H11+'Picks importieren'!$S$2 -> 38.368 | I10: =IF(I$1="",-999,SQRT(($B10-I$1)^2+J$1^2)) -> -999 | J10: =IF('Picks importieren'!J11="",-999,'Picks importieren'!J11+'Picks importieren'!$S$2) -> -999 | K10: =IF(K$1="",-999,SQRT(($B10-K$1)^2+L$1^2)) -> -999 | L10: =IF('Picks importieren'!L11="",-999,'Picks importieren'!L11+'Picks importieren'!$S$2) -> -999 | M10: =IF(M$1="",-999,SQRT(($B10-M$1)^2+N$1^2)) -> -999 | N10: =IF('Picks importieren'!N11="",-999,'Picks importieren'!N11+'Picks importieren'!$S$2) -> -999 | O10: =IF(O$1="",-999,SQRT(($B10-O$1)^2+P$1^2)) -> -999 | P10: =IF('Picks importieren'!P11="",-999,'Picks importieren'!P11+'Picks importieren'!$S$2) -> -999
A11: 9 | B11: ='Picks importieren'!B12 -> 30 | C11: =IF(C$1="","",SQRT(($B11-C$1)^2+D$1^2)) -> 66.271808 | D11: ='Picks importieren'!D12+'Picks importieren'!$S$2 -> 57.1745 | E11: =IF(E$1="","",SQRT(($B11-E$1)^2+F$1^2)) -> 165.00776 | F11: ='Picks importieren'!F12+'Picks importieren'!$S$2 -> 92.5387 | G11: =IF(G$1="","",SQRT(($B11-G$1)^2+H$1^2)) -> 32.549808 | H11: ='Picks importieren'!H12+'Picks importieren'!$S$2 -> 41.1661 | I11: =IF(I$1="",-999,SQRT(($B11-I$1)^2+J$1^2)) -> -999 | J11: =IF('Picks importieren'!J12="",-999,'Picks importieren'!J12+'Picks importieren'!$S$2) -> -999 | K11: =IF(K$1="",-999,SQRT(($B11-K$1)^2+L$1^2)) -> -999 | L11: =IF('Picks importieren'!L12="",-999,'Picks importieren'!L12+'Picks importieren'!$S$2) -> -999 | M11: =IF(M$1="",-999,SQRT(($B11-M$1)^2+N$1^2)) -> -999 | N11: =IF('Picks importieren'!N12="",-999,'Picks importieren'!N12+'Picks importieren'!$S$2) -> -999 | O11: =IF(O$1="",-999,SQRT(($B11-O$1)^2+P$1^2)) -> -999 | P11: =IF('Picks importieren'!P12="",-999,'Picks importieren'!P12+'Picks importieren'!$S$2) -> -999
A12: 10 | B12: ='Picks importieren'!B13 -> 35 | C12: =IF(C$1="","",SQRT(($B12-C$1)^2+D$1^2)) -> 61.273587 | D12: ='Picks importieren'!D13+'Picks importieren'!$S$2 -> 54.517 | E12: =IF(E$1="","",SQRT(($B12-E$1)^2+F$1^2)) -> 160.008 | F12: ='Picks importieren'!F13+'Picks importieren'!$S$2 -> 90.4946 | G12: =IF(G$1="","",SQRT(($B12-G$1)^2+H$1^2)) -> 37.543175 | H12: ='Picks importieren'!H13+'Picks importieren'!$S$2 -> 43.7268 | I12: =IF(I$1="",-999,SQRT(($B12-I$1)^2+J$1^2)) -> -999 | J12: =IF('Picks importieren'!J13="",-999,'Picks importieren'!J13+'Picks importieren'!$S$2) -> -999 | K12: =IF(K$1="",-999,SQRT(($B12-K$1)^2+L$1^2)) -> -999 | L12: =IF('Picks importieren'!L13="",-999,'Picks importieren'!L13+'Picks importieren'!$S$2) -> -999 | M12: =IF(M$1="",-999,SQRT(($B12-M$1)^2+N$1^2)) -> -999 | N12: =IF('Picks importieren'!N13="",-999,'Picks importieren'!N13+'Picks importieren'!$S$2) -> -999 | O12: =IF(O$1="",-999,SQRT(($B12-O$1)^2+P$1^2)) -> -999 | P12: =IF('Picks importieren'!P13="",-999,'Picks importieren'!P13+'Picks importieren'!$S$2) -> -999
A13: 11 | B13: ='Picks importieren'!B14 -> 40 | C13: =IF(C$1="","",SQRT(($B13-C$1)^2+D$1^2)) -> 56.275683 | D13: ='Picks importieren'!D14+'Picks importieren'!$S$2 -> 51.2464 | E13: =IF(E$1="","",SQRT(($B13-E$1)^2+F$1^2)) -> 155.00826 | F13: ='Picks importieren'!F14+'Picks importieren'!$S$2 -> 88.8592 | G13: =IF(G$1="","",SQRT(($B13-G$1)^2+H$1^2)) -> 42.538101 | H13: ='Picks importieren'!H14+'Picks importieren'!$S$2 -> 46.2876 | I13: =IF(I$1="",-999,SQRT(($B13-I$1)^2+J$1^2)) -> -999 | J13: =IF('Picks importieren'!J14="",-999,'Picks importieren'!J14+'Picks importieren'!$S$2) -> -999 | K13: =IF(K$1="",-999,SQRT(($B13-K$1)^2+L$1^2)) -> -999 | L13: =IF('Picks importieren'!L14="",-999,'Picks importieren'!L14+'Picks importieren'!$S$2) -> -999 | M13: =IF(M$1="",-999,SQRT(($B13-M$1)^2+N$1^2)) -> -999 | N13: =IF('Picks importieren'!N14="",-999,'Picks importieren'!N14+'Picks importieren'!$S$2) -> -999 | O13: =IF(O$1="",-999,SQRT(($B13-O$1)^2+P$1^2)) -> -999 | P13: =IF('Picks importieren'!P14="",-999,'Picks importieren'!P14+'Picks importieren'!$S$2) -> -999
A14: 12 | B14: ='Picks importieren'!B15 -> 45 | C14: =IF(C$1="","",SQRT(($B14-C$1)^2+D$1^2)) -> 51.278187 | D14: ='Picks importieren'!D15+'Picks importieren'!$S$2 -> 48.7934 | E14: =IF(E$1="","",SQRT(($B14-E$1)^2+F$1^2)) -> 150.00853 | F14: ='Picks importieren'!F15+'Picks importieren'!$S$2 -> 87.2239 | G14: =IF(G$1="","",SQRT(($B14-G$1)^2+H$1^2)) -> 47.534093 | H14: ='Picks importieren'!H15+'Picks importieren'!$S$2 -> 49.1045 | I14: =IF(I$1="",-999,SQRT(($B14-I$1)^2+J$1^2)) -> -999 | J14: =IF('Picks importieren'!J15="",-999,'Picks importieren'!J15+'Picks importieren'!$S$2) -> -999 | K14: =IF(K$1="",-999,SQRT(($B14-K$1)^2+L$1^2)) -> -999 | L14: =IF('Picks importieren'!L15="",-999,'Picks importieren'!L15+'Picks importieren'!$S$2) -> -999 | M14: =IF(M$1="",-999,SQRT(($B14-M$1)^2+N$1^2)) -> -999 | N14: =IF('Picks importieren'!N15="",-999,'Picks importieren'!N15+'Picks importieren'!$S$2) -> -999 | O14: =IF(O$1="",-999,SQRT(($B14-O$1)^2+P$1^2)) -> -999 | P14: =IF('Picks importieren'!P15="",-999,'Picks importieren'!P15+'Picks importieren'!$S$2) -> -999
... A50: 48 | B50: ='Picks importieren'!B51 -> 192.5 | C50: =IF(C$1="","",SQRT(($B50-C$1)^2+D$1^2)) -> 96.265012 | D50: ='Picks importieren'!D51+'Picks importieren'!$S$2 -> 70.6661 | E50: =IF(E$1="","",SQRT(($B50-E$1)^2+F$1^2)) -> 2.9681644 | F50: ='Picks importieren'!F51+'Picks importieren'!$S$2 -> 5.45678 | G50: =IF(G$1="","",SQRT(($B50-G$1)^2+H$1^2)) -> 195.00831 | H50: ='Picks importieren'!H51+'Picks importieren'!$S$2 -> 99.8079 | I50: =IF(I$1="",-999,SQRT(($B50-I$1)^2+J$1^2)) -> -999 | J50: =IF('Picks importieren'!J51="",-999,'Picks importieren'!J51+'Picks importieren'!$S$2) -> -999 | K50: =IF(K$1="",-999,SQRT(($B50-K$1)^2+L$1^2)) -> -999 | L50: =IF('Picks importieren'!L51="",-999,'Picks importieren'!L51+'Picks importieren'!$S$2) -> -999 | M50: =IF(M$1="",-999,SQRT(($B50-M$1)^2+N$1^2)) -> -999 | N50: =IF('Picks importieren'!N51="",-999,'Picks importieren'!N51+'Picks importieren'!$S$2) -> -999 | O50: =IF(O$1="",-999,SQRT(($B50-O$1)^2+P$1^2)) -> -999 | P50: =IF('Picks importieren'!P51="",-999,'Picks importieren'!P51+'Picks importieren'!$S$2) -> -999
B59: WEITER

Sheet Laufzeitkurven
P1: Version 2.5, 48 channels
B2: Name eingeben: | C2: LVL 150 | F2: Projekt: | G2: 3D-Seismik Erfurt 2026
D49: Auswertung als 2-Schichtfall nach Hagedoorn (Plus-Minus-Methode) | J49: Auswertung als 3-Schichtfall (statistische Auswertung)

Sheet Auswertung 2-Schicht
U1: =Laufzeitkurven!P1 -> Version 2.5, 48 channels
B2: Steigung | C2: Zentral - | D2: Zentral + | E2: Off-end - | F2: Off-end + | G2: Steigung | H2: Plus-Zeiten | I2: Fern - | J2: Fern + | K2: Fern -- | L2: Fern ++ | N2: v0 Zentral | O2: =IF(AND(C5="",D5=""),"",AVERAGE(C5,D5)) -> 557.41929 | P2: m/s | R2: Darstellung der theoretischen LZK mit Picks
B3: von [m] | C3: 80 | D3: 96 | E3: 182 | F3: 0 | G3: von [m] | H3: 10 | N3: v0 Off-end | O3: =IF(AND(E5="",F5=""),"",AVERAGE(E5,F5)) -> 490.97888 | P3: m/s
B4: bis [m] | C4: 96 | D4: 113 | E4: 195 | F4: 10 | G4: bis [m] | H4: 178 | N4: v0 Gesamt | O4: =IF(AND(O3="",O2=""),"",AVERAGE(O3,O2)) -> 524.19908 | P4: m/s
B5: v0 | C5: =IF(C3="","",1000/ABS(SLOPE(Hilfsdaten!B4:B57,Hilfsdaten!$A4:$A57))) -> 557.60295 | D5: =IF(D3="","",1000/ABS(SLOPE(Hilfsdaten!C4:C57,Hilfsdaten!$A4:$A57))) -> 557.23563 | E5: =IF(E3="","",1000/ABS(SLOPE(Hilfsdaten!D4:D57,Hilfsdaten!$A4:$A57))) -> 525.28947 | F5: =IF(F3="","",1000/ABS(SLOPE(Hilfsdaten!E4:E57,Hilfsdaten!$A4:$A57))) -> 456.66829 | G5: v1 | H5: =IF(H3="","",2000/ABS(SLOPE(Hilfsdaten!F4:F57,Hilfsdaten!$A4:$A57))) -> 2560.0779 | I5: =IF(I3="","",1000/ABS(SLOPE(Hilfsdaten!H4:H57,Hilfsdaten!$A4:$A57))) | J5: =IF(J3="","",1000/ABS(SLOPE(Hilfsdaten!I4:I57,Hilfsdaten!$A4:$A57))) | K5: =IF(K3="","",1000/ABS(SLOPE(Hilfsdaten!J4:J57,Hilfsdaten!$A4:$A57))) | L5: =IF(L3="","",1000/ABS(SLOPE(Hilfsdaten!K4:K57,Hilfsdaten!$A4:$A57))) | N5: v1 Off-end | O5: =H5 -> 2560.0779 | P5: m/s
G6: ti1 | H6: =IF(H3="","",AVERAGE(Hilfsdaten!G4:G57)) -> 37.115247 | N6: v1 Fern | O6: =IF(AND(I5="",J5="",K5="",L5=""),"",AVERAGE(I5:L5)) | P6: m/s
B7: Auswahl Anregungspunkte zur Berechnung Plus- und Minuszeiten | N7: v1 Gesamt | O7: =IF(AND(O6="",O5=""),"",AVERAGE(O6,O5)) -> 2560.0779 | P7: m/s
B8: (Off-end = 1; Fern = 2; Fern2 = 3): | H8: 1 | N8: ti1 | O8: =H6 -> 37.115247 | P8: ms
N9: h0 | O9: =IF(O8="","",O8*O3*O5/(2000*SQRT(O5^2-O3^2))) -> 9.2837314 | P9: m
B10: In rot umrandeten Zellen Start und Ende der Zahlenbereiche für Anstieg anpassen (Mauszeiger über entsprechenden Pick im Diagramm halten), entsprechend der linearen Bereiche der Laufzeitkurven!

Sheet Auswertung 3-Schicht
U1: =Laufzeitkurven!P1 -> Version 2.5, 48 channels
C2: Steigung | D2: Zentral - | E2: Zentral + | F2: Off-end - | G2: Off-end + | H2: Fern - | I2: Fern + | J2: Fern -- | K2: Fern ++ | M2: v0 Zentral | N2: =IF(AND(D5="",E5=""),"",AVERAGE(D5,E5)) -> 557.41929 | O2: m/s | R2: Darstellung der theoretischen LZK mit Picks
B3: v0 | C3: von [m] | D3: 80 | E3: 96 | F3: 177 | G3: 0 | M3: v0 Off-end | N3: =IF(AND(G5="",F5=""),"",AVERAGE(G5,F5)) -> 514.24055 | O3: m/s
C4: bis [m] | D4: 96 | E4: 113 | F4: 193 | G4: 10 | M4: v0 Gesamt | N4: =IF(AND(N3="",N2=""),"",AVERAGE(N3,N2,H5:K5)) -> 535.82992 | O4: m/s
C5: v0 | D5: =IF(D3="","",1000/ABS(SLOPE(Hilfsdaten!W4:W57,Hilfsdaten!$A4:$A57))) -> 557.60295 | E5: =IF(E3="","",1000/ABS(SLOPE(Hilfsdaten!X4:X57,Hilfsdaten!$A4:$A57))) -> 557.23563 | F5: =IF(F3="","",1000/ABS(SLOPE(Hilfsdaten!Y4:Y57,Hilfsdaten!$A4:$A57))) -> 571.81281 | G5: =IF(G3="","",1000/ABS(SLOPE(Hilfsdaten!Z4:Z57,Hilfsdaten!$A4:$A57))) -> 456.66829 | H5: =IF(H3="","",1000/ABS(SLOPE(Hilfsdaten!AA4:AA57,Hilfsdaten!$A4:$A57))) | I5: =IF(I3="","",1000/ABS(SLOPE(Hilfsdaten!AB4:AB57,Hilfsdaten!$A4:$A57))) | J5: =IF(J3="","",1000/ABS(SLOPE(Hilfsdaten!AC4:AC57,Hilfsdaten!$A4:$A57))) | K5: =IF(K3="","",1000/ABS(SLOPE(Hilfsdaten!AD4:AD57,Hilfsdaten!$A4:$A57))) | M5: v1 Gesamt | N5: =IF(AND(D8="",E8="",F8="",G8="",H8="",I8="",J8="",K8=""),"",AVERAGE(D8:K8)) -> 1840.4324 | O5: m/s
B6: v1 | C6: von [m] | D6: 10 | E6: 112 | F6: 107 | G6: 10 | M6: ti1 | N6: =IF(AND(D9="",E9="",F9="",G9="",H9="",I9="",J9="",K9=""),"",AVERAGE(D9:K9)) -> 21.549971 | O6: ms
C7: bis [m] | D7: 80 | E7: 177 | F7: 178 | G7: 75 | M7: h0 | N7: =IF(N6="","",N4*N6/(2000*COS(ASIN(N4/N5)))) -> 6.0349994 | O7: m
C8: v1 | D8: =IF(D6="","",1000/ABS(SLOPE(Hilfsdaten!AE4:AE57,Hilfsdaten!$A4:$A57))) -> 1862.6057 | E8: =IF(E6="","",1000/ABS(SLOPE(Hilfsdaten!AF4:AF57,Hilfsdaten!$A4:$A57))) -> 1887.9768 | F8: =IF(F6="","",1000/ABS(SLOPE(Hilfsdaten!AG4:AG57,Hilfsdaten!$A4:$A57))) -> 1811.6362 | G8: =IF(G6="","",1000/ABS(SLOPE(Hilfsdaten!AH4:AH57,Hilfsdaten!$A4:$A57))) -> 1799.5111 | H8: =IF(H6="","",1000/ABS(SLOPE(Hilfsdaten!AI4:AI57,Hilfsdaten!$A4:$A57))) | I8: =IF(I6="","",1000/ABS(SLOPE(Hilfsdaten!AJ4:AJ57,Hilfsdaten!$A4:$A57))) | J8: =IF(J6="","",1000/ABS(SLOPE(Hilfsdaten!AK4:AK57,Hilfsdaten!$A4:$A57))) | K8: =IF(K6="","",1000/ABS(SLOPE(Hilfsdaten!AL4:AL57,Hilfsdaten!$A4:$A57))) | M8: v2 Gesamt | N8: =IF(AND(D12="",E12="",F12="",G12="",H12="",I12="",J12="",K12=""),"",AVERAGE(D12:K12)) -> 3267.9973 | O8: m/s
C9: ti1 | D9: =IF(D6="","",INTERCEPT(Hilfsdaten!AE4:AE57,T0_Korrektur!C3:C56)) -> 20.957572 | E9: =IF(E6="","",INTERCEPT(Hilfsdaten!AF4:AF57,T0_Korrektur!C3:C56)) -> 21.642928 | F9: =IF(F6="","",INTERCEPT(Hilfsdaten!AG4:AG57,T0_Korrektur!E3:E56)) -> 20.980749 | G9: =IF(G6="","",INTERCEPT(Hilfsdaten!AH4:AH57,T0_Korrektur!G3:G56)) -> 22.618635 | H9: =IF(H6="","",INTERCEPT(Hilfsdaten!AI4:AI57,T0_Korrektur!I3:I56)) | I9: =IF(I6="","",INTERCEPT(Hilfsdaten!AJ4:AJ57,T0_Korrektur!K3:K56)) | J9: =IF(J6="","",INTERCEPT(Hilfsdaten!AK4:AK57,T0_Korrektur!M3:M56)) | K9: =IF(K6="","",INTERCEPT(Hilfsdaten!AL4:AL57,T0_Korrektur!O3:O56)) | M9: ti2 | N9: =IF(AND(D13="",E13="",F13="",G13="",H13="",I13="",J13="",K13=""),"",AVERAGE(D13:K13)) -> 41.370316 | O9: ms
B10: v2 | C10: von [m] | D10: 0 | E10: 177 | F10: 0 | G10: 80 | M10: h1 | N10: =IF(N9="","",N5*(N9-2*N7*COS(ASIN(N4/N8))/N4)/(2000*COS(ASIN(N5/N8)))) -> 46.045315 | O10: m
C11: bis [m] | D11: 10 | E11: 193 | F11: 107 | G11: 193 | N11: =IF(N9="","",N5*(0.001*N9-2*N7*COS(ASIN(N4/N8))/N4)/(2*COS(ASIN(N5/N8)))) -> 21.32477 | O11: =IF(N9="","",N5*(N9-2000*N7*COS(ASIN(N4/N8))/N4)/(2000*COS(ASIN(N5/N8)))) -> 21.32477
C12: v2 | D12: =IF(D10="","",1000/ABS(SLOPE(Hilfsdaten!AM4:AM57,Hilfsdaten!$A4:$A57))) -> 3216.29 | E12: =IF(E10="","",1000/ABS(SLOPE(Hilfsdaten!AN4:AN57,Hilfsdaten!$A4:$A57))) -> 3106.7601 | F12: =IF(F10="","",1000/ABS(SLOPE(Hilfsdaten!AO4:AO57,Hilfsdaten!$A4:$A57))) -> 3291.0205 | G12: =IF(G10="","",1000/ABS(SLOPE(Hilfsdaten!AP4:AP57,Hilfsdaten!$A4:$A57))) -> 3457.9185 | H12: =IF(H10="","",1000/ABS(SLOPE(Hilfsdaten!AQ4:AQ57,Hilfsdaten!$A4:$A57))) | I12: =IF(I10="","",1000/ABS(SLOPE(Hilfsdaten!AR4:AR57,Hilfsdaten!$A4:$A57))) | J12: =IF(J10="","",1000/ABS(SLOPE(Hilfsdaten!AS4:AS57,Hilfsdaten!$A4:$A57))) | K12: =IF(K10="","",1000/ABS(SLOPE(Hilfsdaten!AT4:AT57,Hilfsdaten!$A4:$A57))) | M12: In rot umrandete Zellen Start und Ende der Zahlenbereiche für Anstieg anpassen (Mauszeiger über entsprechenden Pick im Diagramm halten), entsprechend der linearen Bereiche der Laufzeitkurven!
C13: ti2 | D13: =IF(D10="","",INTERCEPT(Hilfsdaten!AM4:AM57,T0_Korrektur!C3:C56)) -> 39.574831 | E13: =IF(E10="","",INTERCEPT(Hilfsdaten!AN4:AN57,T0_Korrektur!C3:C56)) -> 39.831616 | F13: =IF(F10="","",INTERCEPT(Hilfsdaten!AO4:AO57,T0_Korrektur!E3:E56)) -> 42.123219 | G13: =IF(G10="","",INTERCEPT(Hilfsdaten!AP4:AP57,T0_Korrektur!G3:G56)) -> 43.951598 | H13: =IF(H10="","",INTERCEPT(Hilfsdaten!AQ4:AQ57,T0_Korrektur!I3:I56)) | I13: =IF(I10="","",INTERCEPT(Hilfsdaten!AR4:AR57,T0_Korrektur!K3:K56)) | J13: =IF(J10="","",INTERCEPT(Hilfsdaten!AS4:AS57,T0_Korrektur!M3:M56)) | K13: =IF(K10="","",INTERCEPT(Hilfsdaten!AT4:AT57,T0_Korrektur!O3:O56))

Sheet Fit
P4: RMS-Fehler 2-Schichtfall
P6: =Hilfsdaten!BV3 -> 12.051379 | Q6: ms
P8: RMS-Fehler 3-Schichtfall
P10: =Hilfsdaten!BZ3 -> 7.0681307 | Q10: ms
P12: RMS-Fehler nur für Zentral-, Hin- und Rückschuss berechnet
P15: Ergebnisse:
Q17: 2-Schicht | R17: 3-Schicht
P18: v0 [m/s] | Q18: ='Auswertung 2-Schicht'!O4 -> 524.19908 | R18: ='Auswertung 3-Schicht'!N4 -> 535.82992
P19: v1 [m/s] | Q19: ='Auswertung 2-Schicht'!O7 -> 2560.0779 | R19: ='Auswertung 3-Schicht'!N5 -> 1840.4324
P20: h0 [m] | Q20: ='Auswertung 2-Schicht'!O9 -> 9.2837314 | R20: ='Auswertung 3-Schicht'!N7 -> 6.0349994
P21: v2 [m/s] | R21: ='Auswertung 3-Schicht'!N8 -> 3267.9973
P22: h1 [m] | R22: ='Auswertung 3-Schicht'!N10 -> 46.045315
D49: Zurück zur 2-Schichtfallauswertung | J49: Zurück zur 3-Schichtfallauswertung

Sheet Berechnung
J1: =(INTERCEPT(T0_Korrektur!F3:F12,T0_Korrektur!G3:G12)+INTERCEPT(T0_Korrektur!H41:H50,T0_Korrektur!E41:E50))/2 -> 101.20457 | O1: =(INTERCEPT(T0_Korrektur!J3:J12,T0_Korrektur!K3:K12)+INTERCEPT(T0_Korrektur!L41:L50,T0_Korrektur!I41:I50))/2 -> #DIV/0! | T1: =(INTERCEPT(T0_Korrektur!N3:N12,T0_Korrektur!O3:O12)+INTERCEPT(T0_Korrektur!P41:P50,T0_Korrektur!M41:M50))/2 -> #DIV/0!
A2: Trace | B2: m | C2: T zentral - | D2: T zentral + | E2: T off-end - | F2: T off-end + | G2: T off-end - corr. | H2: Difference | I2: Pluszeiten | J2: Minuszeiten | K2: T fern- | L2: T fern+ | M2: Fern Difference | N2: Fern Pluszeiten | O2: Fern Minuszeiten | P2: T fern-- | Q2: T fern++ | R2: Fern2 Difference | S2: Fern2 Pluszeiten | T2: Fern2 Minuszeiten
A3: 1 | B3: ='Picks importieren'!B4 -> 0 | C3: =T0_Korrektur!D3*ABS(T0_Korrektur!B3-T0_Korrektur!C$1)/T0_Korrektur!C3 -> 69.428671 | E3: =T0_Korrektur!F3*ABS(T0_Korrektur!B3-T0_Korrektur!E$1)/T0_Korrektur!E3 -> 100.9166 | F3: =T0_Korrektur!H3*ABS(T0_Korrektur!B3-T0_Korrektur!G$1)/T0_Korrektur!G3 -> 6.4190662 | G3: =E3+$F$50-$E$3 -> 99.803648 | H3: =$G$3-G3 -> 0 | I3: =IF(H3="","",F3-E3+E$3-F$3) -> -2.6645353e-15 | J3: =F3+E3-J$1 -> 6.1311032 | K3: =IF(T0_Korrektur!I3=-999,-999,T0_Korrektur!J3*ABS(T0_Korrektur!B3-T0_Korrektur!I$1)/T0_Korrektur!I3) -> -999 | L3: =IF(T0_Korrektur!K3=-999,-999,T0_Korrektur!L3*ABS(T0_Korrektur!B3-T0_Korrektur!K$1)/T0_Korrektur!K3) -> -999 | M3: =IF(K3="","",$K$3-K3) -> 0 | N3: =IF(M3="","",L3-K3+K$3-L$3) -> 0 | O3: =L3+K3-O$1 -> #DIV/0! | P3: =IF(T0_Korrektur!M3=-999,-999,T0_Korrektur!N3*ABS(T0_Korrektur!B3-T0_Korrektur!M$1)/T0_Korrektur!M3) -> -999 | Q3: =IF(T0_Korrektur!O3=-999,-999,T0_Korrektur!P3*ABS(T0_Korrektur!B3-T0_Korrektur!O$1)/T0_Korrektur!O3) -> -999 | R3: =IF(P3="","",$P$3-P3) -> 0 | S3: =IF(R3="","",Q3-P3+P$3-Q$3) -> 0 | T3: =Q3+P3-T$1 -> #DIV/0!
A4: 2 | B4: ='Picks importieren'!B5 -> 2.5 | C4: =T0_Korrektur!D4*ABS(T0_Korrektur!B4-T0_Korrektur!C$1)/T0_Korrektur!C4 -> 68.814987 | E4: =T0_Korrektur!F4*ABS(T0_Korrektur!B4-T0_Korrektur!E$1)/T0_Korrektur!E4 -> 100.50753 | F4: =T0_Korrektur!H4*ABS(T0_Korrektur!B4-T0_Korrektur!G$1)/T0_Korrektur!G4 -> 12.827589 | G4: =E4+$F$50-$E$3 -> 99.394573 | H4: =$G$3-G4 -> 0.40907468 | I4: =IF(H4="","",F4-E4+E$3-F$3) -> 6.817597 | J4: =F4+E4-J$1 -> 12.130551 | K4: =IF(T0_Korrektur!I4=-999,-999,T0_Korrektur!J4*ABS(T0_Korrektur!B4-T0_Korrektur!I$1)/T0_Korrektur!I4) -> -999 | L4: =IF(T0_Korrektur!K4=-999,-999,T0_Korrektur!L4*ABS(T0_Korrektur!B4-T0_Korrektur!K$1)/T0_Korrektur!K4) -> -999 | M4: =IF(K4="","",$K$3-K4) -> 0 | N4: =IF(M4="","",L4-K4+K$3-L$3) -> 0 | O4: =L4+K4-O$1 -> #DIV/0! | P4: =IF(T0_Korrektur!M4=-999,-999,T0_Korrektur!N4*ABS(T0_Korrektur!B4-T0_Korrektur!M$1)/T0_Korrektur!M4) -> -999 | Q4: =IF(T0_Korrektur!O4=-999,-999,T0_Korrektur!P4*ABS(T0_Korrektur!B4-T0_Korrektur!O$1)/T0_Korrektur!O4) -> -999 | R4: =IF(P4="","",$P$3-P4) -> 0 | S4: =IF(R4="","",Q4-P4+P$3-Q$3) -> 0 | T4: =Q4+P4-T$1 -> #DIV/0!
A5: 3 | B5: ='Picks importieren'!B6 -> 5 | C5: =T0_Korrektur!D5*ABS(T0_Korrektur!B5-T0_Korrektur!C$1)/T0_Korrektur!C5 -> 67.996801 | E5: =T0_Korrektur!F5*ABS(T0_Korrektur!B5-T0_Korrektur!E$1)/T0_Korrektur!E5 -> 100.09845 | F5: =T0_Korrektur!H5*ABS(T0_Korrektur!B5-T0_Korrektur!G$1)/T0_Korrektur!G5 -> 17.992277 | G5: =E5+$F$50-$E$3 -> 98.985496 | H5: =$G$3-G5 -> 0.81815213 | I5: =IF(H5="","",F5-E5+E$3-F$3) -> 12.391363 | J5: =F5+E5-J$1 -> 16.886162 | K5: =IF(T0_Korrektur!I5=-999,-999,T0_Korrektur!J5*ABS(T0_Korrektur!B5-T0_Korrektur!I$1)/T0_Korrektur!I5) -> -999 | L5: =IF(T0_Korrektur!K5=-999,-999,T0_Korrektur!L5*ABS(T0_Korrektur!B5-T0_Korrektur!K$1)/T0_Korrektur!K5) -> -999 | M5: =IF(K5="","",$K$3-K5) -> 0 | N5: =IF(M5="","",L5-K5+K$3-L$3) -> 0 | O5: =L5+K5-O$1 -> #DIV/0! | P5: =IF(T0_Korrektur!M5=-999,-999,T0_Korrektur!N5*ABS(T0_Korrektur!B5-T0_Korrektur!M$1)/T0_Korrektur!M5) -> -999 | Q5: =IF(T0_Korrektur!O5=-999,-999,T0_Korrektur!P5*ABS(T0_Korrektur!B5-T0_Korrektur!O$1)/T0_Korrektur!O5) -> -999 | R5: =IF(P5="","",$P$3-P5) -> 0 | S5: =IF(R5="","",Q5-P5+P$3-Q$3) -> 0 | T5: =Q5+P5-T$1 -> #DIV/0!
A6: 4 | B6: ='Picks importieren'!B7 -> 7.5 | C6: =T0_Korrektur!D6*ABS(T0_Korrektur!B6-T0_Korrektur!C$1)/T0_Korrektur!C6 -> 67.178577 | E6: =T0_Korrektur!F6*ABS(T0_Korrektur!B6-T0_Korrektur!E$1)/T0_Korrektur!E6 -> 99.280885 | F6: =T0_Korrektur!H6*ABS(T0_Korrektur!B6-T0_Korrektur!G$1)/T0_Korrektur!G6 -> 23.251036 | G6: =E6+$F$50-$E$3 -> 98.16793 | H6: =$G$3-G6 -> 1.6357176 | I6: =IF(H6="","",F6-E6+E$3-F$3) -> 18.467687 | J6: =F6+E6-J$1 -> 21.327355 | K6: =IF(T0_Korrektur!I6=-999,-999,T0_Korrektur!J6*ABS(T0_Korrektur!B6-T0_Korrektur!I$1)/T0_Korrektur!I6) -> -999 | L6: =IF(T0_Korrektur!K6=-999,-999,T0_Korrektur!L6*ABS(T0_Korrektur!B6-T0_Korrektur!K$1)/T0_Korrektur!K6) -> -999 | M6: =IF(K6="","",$K$3-K6) -> 0 | N6: =IF(M6="","",L6-K6+K$3-L$3) -> 0 | O6: =L6+K6-O$1 -> #DIV/0! | P6: =IF(T0_Korrektur!M6=-999,-999,T0_Korrektur!N6*ABS(T0_Korrektur!B6-T0_Korrektur!M$1)/T0_Korrektur!M6) -> -999 | Q6: =IF(T0_Korrektur!O6=-999,-999,T0_Korrektur!P6*ABS(T0_Korrektur!B6-T0_Korrektur!O$1)/T0_Korrektur!O6) -> -999 | R6: =IF(P6="","",$P$3-P6) -> 0 | S6: =IF(R6="","",Q6-P6+P$3-Q$3) -> 0 | T6: =Q6+P6-T$1 -> #DIV/0!
A7: 5 | B7: ='Picks importieren'!B8 -> 10 | C7: =T0_Korrektur!D7*ABS(T0_Korrektur!B7-T0_Korrektur!C$1)/T0_Korrektur!C7 -> 66.360411 | E7: =T0_Korrektur!F7*ABS(T0_Korrektur!B7-T0_Korrektur!E$1)/T0_Korrektur!E7 -> 98.463218 | F7: =T0_Korrektur!H7*ABS(T0_Korrektur!B7-T0_Korrektur!G$1)/T0_Korrektur!G7 -> 28.579508 | G7: =E7+$F$50-$E$3 -> 97.350263 | H7: =$G$3-G7 -> 2.4533854 | I7: =IF(H7="","",F7-E7+E$3-F$3) -> 24.613827 | J7: =F7+E7-J$1 -> 25.83816 | K7: =IF(T0_Korrektur!I7=-999,-999,T0_Korrektur!J7*ABS(T0_Korrektur!B7-T0_Korrektur!I$1)/T0_Korrektur!I7) -> -999 | L7: =IF(T0_Korrektur!K7=-999,-999,T0_Korrektur!L7*ABS(T0_Korrektur!B7-T0_Korrektur!K$1)/T0_Korrektur!K7) -> -999 | M7: =IF(K7="","",$K$3-K7) -> 0 | N7: =IF(M7="","",L7-K7+K$3-L$3) -> 0 | O7: =L7+K7-O$1 -> #DIV/0! | P7: =IF(T0_Korrektur!M7=-999,-999,T0_Korrektur!N7*ABS(T0_Korrektur!B7-T0_Korrektur!M$1)/T0_Korrektur!M7) -> -999 | Q7: =IF(T0_Korrektur!O7=-999,-999,T0_Korrektur!P7*ABS(T0_Korrektur!B7-T0_Korrektur!O$1)/T0_Korrektur!O7) -> -999 | R7: =IF(P7="","",$P$3-P7) -> 0 | S7: =IF(R7="","",Q7-P7+P$3-Q$3) -> 0 | T7: =Q7+P7-T$1 -> #DIV/0!
A8: 6 | B8: ='Picks importieren'!B9 -> 15 | C8: =T0_Korrektur!D8*ABS(T0_Korrektur!B8-T0_Korrektur!C$1)/T0_Korrektur!C8 -> 63.701858 | E8: =T0_Korrektur!F8*ABS(T0_Korrektur!B8-T0_Korrektur!E$1)/T0_Korrektur!E8 -> 97.032067 | F8: =T0_Korrektur!H8*ABS(T0_Korrektur!B8-T0_Korrektur!G$1)/T0_Korrektur!G8 -> 32.543803 | G8: =E8+$F$50-$E$3 -> 95.919112 | H8: =$G$3-G8 -> 3.8845363 | I8: =IF(H8="","",F8-E8+E$3-F$3) -> 30.009273 | J8: =F8+E8-J$1 -> 28.371304 | K8: =IF(T0_Korrektur!I8=-999,-999,T0_Korrektur!J8*ABS(T0_Korrektur!B8-T0_Korrektur!I$1)/T0_Korrektur!I8) -> -999 | L8: =IF(T0_Korrektur!K8=-999,-999,T0_Korrektur!L8*ABS(T0_Korrektur!B8-T0_Korrektur!K$1)/T0_Korrektur!K8) -> -999 | M8: =IF(K8="","",$K$3-K8) -> 0 | N8: =IF(M8="","",L8-K8+K$3-L$3) -> 0 | O8: =L8+K8-O$1 -> #DIV/0! | P8: =IF(T0_Korrektur!M8=-999,-999,T0_Korrektur!N8*ABS(T0_Korrektur!B8-T0_Korrektur!M$1)/T0_Korrektur!M8) -> -999 | Q8: =IF(T0_Korrektur!O8=-999,-999,T0_Korrektur!P8*ABS(T0_Korrektur!B8-T0_Korrektur!O$1)/T0_Korrektur!O8) -> -999 | R8: =IF(P8="","",$P$3-P8) -> 0 | S8: =IF(R8="","",Q8-P8+P$3-Q$3) -> 0 | T8: =Q8+P8-T$1 -> #DIV/0!
A9: 7 | B9: ='Picks importieren'!B10 -> 20 | C9: =T0_Korrektur!D9*ABS(T0_Korrektur!B9-T0_Korrektur!C$1)/T0_Korrektur!C9 -> 61.860727 | E9: =T0_Korrektur!F9*ABS(T0_Korrektur!B9-T0_Korrektur!E$1)/T0_Korrektur!E9 -> 95.601004 | F9: =T0_Korrektur!H9*ABS(T0_Korrektur!B9-T0_Korrektur!G$1)/T0_Korrektur!G9 -> 35.674424 | G9: =E9+$F$50-$E$3 -> 94.488049 | H9: =$G$3-G9 -> 5.3155986 | I9: =IF(H9="","",F9-E9+E$3-F$3) -> 34.570956 | J9: =F9+E9-J$1 -> 30.070862 | K9: =IF(T0_Korrektur!I9=-999,-999,T0_Korrektur!J9*ABS(T0_Korrektur!B9-T0_Korrektur!I$1)/T0_Korrektur!I9) -> -999 | L9: =IF(T0_Korrektur!K9=-999,-999,T0_Korrektur!L9*ABS(T0_Korrektur!B9-T0_Korrektur!K$1)/T0_Korrektur!K9) -> -999 | M9: =IF(K9="","",$K$3-K9) -> 0 | N9: =IF(M9="","",L9-K9+K$3-L$3) -> 0 | O9: =L9+K9-O$1 -> #DIV/0! | P9: =IF(T0_Korrektur!M9=-999,-999,T0_Korrektur!N9*ABS(T0_Korrektur!B9-T0_Korrektur!M$1)/T0_Korrektur!M9) -> -999 | Q9: =IF(T0_Korrektur!O9=-999,-999,T0_Korrektur!P9*ABS(T0_Korrektur!B9-T0_Korrektur!O$1)/T0_Korrektur!O9) -> -999 | R9: =IF(P9="","",$P$3-P9) -> 0 | S9: =IF(R9="","",Q9-P9+P$3-Q$3) -> 0 | T9: =Q9+P9-T$1 -> #DIV/0!
A10: 8 | B10: ='Picks importieren'!B11 -> 25 | C10: =T0_Korrektur!D10*ABS(T0_Korrektur!B10-T0_Korrektur!C$1)/T0_Korrektur!C10 -> 59.814877 | E10: =T0_Korrektur!F10*ABS(T0_Korrektur!B10-T0_Korrektur!E$1)/T0_Korrektur!E10 -> 94.37432 | F10: =T0_Korrektur!H10*ABS(T0_Korrektur!B10-T0_Korrektur!G$1)/T0_Korrektur!G10 -> 38.286073 | G10: =E10+$F$50-$E$3 -> 93.261365 | H10: =$G$3-G10 -> 6.5422828 | I10: =IF(H10="","",F10-E10+E$3-F$3) -> 38.40929 | J10: =F10+E10-J$1 -> 31.455827 | K10: =IF(T0_Korrektur!I10=-999,-999,T0_Korrektur!J10*ABS(T0_Korrektur!B10-T0_Korrektur!I$1)/T0_Korrektur!I10) -> -999 | L10: =IF(T0_Korrektur!K10=-999,-999,T0_Korrektur!L10*ABS(T0_Korrektur!B10-T0_Korrektur!K$1)/T0_Korrektur!K10) -> -999 | M10: =IF(K10="","",$K$3-K10) -> 0 | N10: =IF(M10="","",L10-K10+K$3-L$3) -> 0 | O10: =L10+K10-O$1 -> #DIV/0! | P10: =IF(T0_Korrektur!M10=-999,-999,T0_Korrektur!N10*ABS(T0_Korrektur!B10-T0_Korrektur!M$1)/T0_Korrektur!M10) -> -999 | Q10: =IF(T0_Korrektur!O10=-999,-999,T0_Korrektur!P10*ABS(T0_Korrektur!B10-T0_Korrektur!O$1)/T0_Korrektur!O10) -> -999 | R10: =IF(P10="","",$P$3-P10) -> 0 | S10: =IF(R10="","",Q10-P10+P$3-Q$3) -> 0 | T10: =Q10+P10-T$1 -> #DIV/0!
A11: 9 | B11: ='Picks importieren'!B12 -> 30 | C11: =T0_Korrektur!D11*ABS(T0_Korrektur!B11-T0_Korrektur!C$1)/T0_Korrektur!C11 -> 57.155686 | E11: =T0_Korrektur!F11*ABS(T0_Korrektur!B11-T0_Korrektur!E$1)/T0_Korrektur!E11 -> 92.53435 | F11: =T0_Korrektur!H11*ABS(T0_Korrektur!B11-T0_Korrektur!G$1)/T0_Korrektur!G11 -> 41.103107 | G11: =E11+$F$50-$E$3 -> 91.421395 | H11: =$G$3-G11 -> 8.3822535 | I11: =IF(H11="","",F11-E11+E$3-F$3) -> 43.066295 | J11: =F11+E11-J$1 -> 32.432891 | K11: =IF(T0_Korrektur!I11=-999,-999,T0_Korrektur!J11*ABS(T0_Korrektur!B11-T0_Korrektur!I$1)/T0_Korrektur!I11) -> -999 | L11: =IF(T0_Korrektur!K11=-999,-999,T0_Korrektur!L11*ABS(T0_Korrektur!B11-T0_Korrektur!K$1)/T0_Korrektur!K11) -> -999 | M11: =IF(K11="","",$K$3-K11) -> 0 | N11: =IF(M11="","",L11-K11+K$3-L$3) -> 0 | O11: =L11+K11-O$1 -> #DIV/0! | P11: =IF(T0_Korrektur!M11=-999,-999,T0_Korrektur!N11*ABS(T0_Korrektur!B11-T0_Korrektur!M$1)/T0_Korrektur!M11) -> -999 | Q11: =IF(T0_Korrektur!O11=-999,-999,T0_Korrektur!P11*ABS(T0_Korrektur!B11-T0_Korrektur!O$1)/T0_Korrektur!O11) -> -999 | R11: =IF(P11="","",$P$3-P11) -> 0 | S11: =IF(R11="","",Q11-P11+P$3-Q$3) -> 0 | T11: =Q11+P11-T$1 -> #DIV/0!
A12: 10 | B12: ='Picks importieren'!B13 -> 35 | C12: =T0_Korrektur!D12*ABS(T0_Korrektur!B12-T0_Korrektur!C$1)/T0_Korrektur!C12 -> 54.496014 | E12: =T0_Korrektur!F12*ABS(T0_Korrektur!B12-T0_Korrektur!E$1)/T0_Korrektur!E12 -> 90.490076 | F12: =T0_Korrektur!H12*ABS(T0_Korrektur!B12-T0_Korrektur!G$1)/T0_Korrektur!G12 -> 43.676514 | G12: =E12+$F$50-$E$3 -> 89.377121 | H12: =$G$3-G12 -> 10.426527 | I12: =IF(H12="","",F12-E12+E$3-F$3) -> 47.683975 | J12: =F12+E12-J$1 -> 32.962023 | K12: =IF(T0_Korrektur!I12=-999,-999,T0_Korrektur!J12*ABS(T0_Korrektur!B12-T0_Korrektur!I$1)/T0_Korrektur!I12) -> -999 | L12: =IF(T0_Korrektur!K12=-999,-999,T0_Korrektur!L12*ABS(T0_Korrektur!B12-T0_Korrektur!K$1)/T0_Korrektur!K12) -> -999 | M12: =IF(K12="","",$K$3-K12) -> 0 | N12: =IF(M12="","",L12-K12+K$3-L$3) -> 0 | O12: =L12+K12-O$1 -> #DIV/0! | P12: =IF(T0_Korrektur!M12=-999,-999,T0_Korrektur!N12*ABS(T0_Korrektur!B12-T0_Korrektur!M$1)/T0_Korrektur!M12) -> -999 | Q12: =IF(T0_Korrektur!O12=-999,-999,T0_Korrektur!P12*ABS(T0_Korrektur!B12-T0_Korrektur!O$1)/T0_Korrektur!O12) -> -999 | R12: =IF(P12="","",$P$3-P12) -> 0 | S12: =IF(R12="","",Q12-P12+P$3-Q$3) -> 0 | T12: =Q12+P12-T$1 -> #DIV/0!
A13: 11 | B13: ='Picks importieren'!B14 -> 40 | C13: =T0_Korrektur!D13*ABS(T0_Korrektur!B13-T0_Korrektur!C$1)/T0_Korrektur!C13 -> 51.223012 | E13: =T0_Korrektur!F13*ABS(T0_Korrektur!B13-T0_Korrektur!E$1)/T0_Korrektur!E13 -> 88.854466 | F13: =T0_Korrektur!H13*ABS(T0_Korrektur!B13-T0_Korrektur!G$1)/T0_Korrektur!G13 -> 46.246141 | G13: =E13+$F$50-$E$3 -> 87.741511 | H13: =$G$3-G13 -> 12.062137 | I13: =IF(H13="","",F13-E13+E$3-F$3) -> 51.889212 | J13: =F13+E13-J$1 -> 33.896041 | K13: =IF(T0_Korrektur!I13=-999,-999,T0_Korrektur!J13*ABS(T0_Korrektur!B13-T0_Korrektur!I$1)/T0_Korrektur!I13) -> -999 | L13: =IF(T0_Korrektur!K13=-999,-999,T0_Korrektur!L13*ABS(T0_Korrektur!B13-T0_Korrektur!K$1)/T0_Korrektur!K13) -> -999 | M13: =IF(K13="","",$K$3-K13) -> 0 | N13: =IF(M13="","",L13-K13+K$3-L$3) -> 0 | O13: =L13+K13-O$1 -> #DIV/0! | P13: =IF(T0_Korrektur!M13=-999,-999,T0_Korrektur!N13*ABS(T0_Korrektur!B13-T0_Korrektur!M$1)/T0_Korrektur!M13) -> -999 | Q13: =IF(T0_Korrektur!O13=-999,-999,T0_Korrektur!P13*ABS(T0_Korrektur!B13-T0_Korrektur!O$1)/T0_Korrektur!O13) -> -999 | R13: =IF(P13="","",$P$3-P13) -> 0 | S13: =IF(R13="","",Q13-P13+P$3-Q$3) -> 0 | T13: =Q13+P13-T$1 -> #DIV/0!
A14: 12 | B14: ='Picks importieren'!B15 -> 45 | C14: =T0_Korrektur!D14*ABS(T0_Korrektur!B14-T0_Korrektur!C$1)/T0_Korrektur!C14 -> 48.766579 | E14: =T0_Korrektur!F14*ABS(T0_Korrektur!B14-T0_Korrektur!E$1)/T0_Korrektur!E14 -> 87.218938 | F14: =T0_Korrektur!H14*ABS(T0_Korrektur!B14-T0_Korrektur!G$1)/T0_Korrektur!G14 -> 49.069281 | G14: =E14+$F$50-$E$3 -> 86.105983 | H14: =$G$3-G14 -> 13.697665 | I14: =IF(H14="","",F14-E14+E$3-F$3) -> 56.347879 | J14: =F14+E14-J$1 -> 35.083653 | K14: =IF(T0_Korrektur!I14=-999,-999,T0_Korrektur!J14*ABS(T0_Korrektur!B14-T0_Korrektur!I$1)/T0_Korrektur!I14) -> -999 | L14: =IF(T0_Korrektur!K14=-999,-999,T0_Korrektur!L14*ABS(T0_Korrektur!B14-T0_Korrektur!K$1)/T0_Korrektur!K14) -> -999 | M14: =IF(K14="","",$K$3-K14) -> 0 | N14: =IF(M14="","",L14-K14+K$3-L$3) -> 0 | O14: =L14+K14-O$1 -> #DIV/0! | P14: =IF(T0_Korrektur!M14=-999,-999,T0_Korrektur!N14*ABS(T0_Korrektur!B14-T0_Korrektur!M$1)/T0_Korrektur!M14) -> -999 | Q14: =IF(T0_Korrektur!O14=-999,-999,T0_Korrektur!P14*ABS(T0_Korrektur!B14-T0_Korrektur!O$1)/T0_Korrektur!O14) -> -999 | R14: =IF(P14="","",$P$3-P14) -> 0 | S14: =IF(R14="","",Q14-P14+P$3-Q$3) -> 0 | T14: =Q14+P14-T$1 -> #DIV/0!
... A26: 24 | B26: ='Picks importieren'!B27 -> 95 | C26: =T0_Korrektur!D26*ABS(T0_Korrektur!B26-T0_Korrektur!C$1)/T0_Korrektur!C26 -> 1.9004952 | E26: =T0_Korrektur!F26*ABS(T0_Korrektur!B26-T0_Korrektur!E$1)/T0_Korrektur!E26 -> 72.598608 | F26: =T0_Korrektur!H26*ABS(T0_Korrektur!B26-T0_Korrektur!G$1)/T0_Korrektur!G26 -> 71.24306 | G26: =E26+$F$50-$E$3 -> 71.485653 | H26: =$G$3-G26 -> 28.317995 | I26: =IF(H26="","",F26-E26+E$3-F$3) -> 93.141989 | J26: =F26+E26-J$1 -> 42.637102 | K26: =IF(T0_Korrektur!I26=-999,-999,T0_Korrektur!J26*ABS(T0_Korrektur!B26-T0_Korrektur!I$1)/T0_Korrektur!I26) -> -999 | L26: =IF(T0_Korrektur!K26=-999,-999,T0_Korrektur!L26*ABS(T0_Korrektur!B26-T0_Korrektur!K$1)/T0_Korrektur!K26) -> -999 | M26: =IF(K26="","",$K$3-K26) -> 0 | N26: =IF(M26="","",L26-K26+K$3-L$3) -> 0 | O26: =L26+K26-O$1 -> #DIV/0! | P26: =IF(T0_Korrektur!M26=-999,-999,T0_Korrektur!N26*ABS(T0_Korrektur!B26-T0_Korrektur!M$1)/T0_Korrektur!M26) -> -999 | Q26: =IF(T0_Korrektur!O26=-999,-999,T0_Korrektur!P26*ABS(T0_Korrektur!B26-T0_Korrektur!O$1)/T0_Korrektur!O26) -> -999 | R26: =IF(P26="","",$P$3-P26) -> 0 | S26: =IF(R26="","",Q26-P26+P$3-Q$3) -> 0 | T26: =Q26+P26-T$1 -> #DIV/0!
A27: 25 | B27: ='Picks importieren'!B28 -> 97.5 | D27: =T0_Korrektur!D27*ABS(T0_Korrektur!B27-T0_Korrektur!C$1)/T0_Korrektur!C27 -> 2.384881 | E27: =T0_Korrektur!F27*ABS(T0_Korrektur!B27-T0_Korrektur!E$1)/T0_Korrektur!E27 -> 71.703946 | F27: =T0_Korrektur!H27*ABS(T0_Korrektur!B27-T0_Korrektur!G$1)/T0_Korrektur!G27 -> 72.267794 | G27: =E27+$F$50-$E$3 -> 70.590991 | H27: =$G$3-G27 -> 29.212657 | I27: =IF(H27="","",F27-E27+E$3-F$3) -> 95.061385 | J27: =F27+E27-J$1 -> 42.767173 | K27: =IF(T0_Korrektur!I27=-999,-999,T0_Korrektur!J27*ABS(T0_Korrektur!B27-T0_Korrektur!I$1)/T0_Korrektur!I27) -> -999 | L27: =IF(T0_Korrektur!K27=-999,-999,T0_Korrektur!L27*ABS(T0_Korrektur!B27-T0_Korrektur!K$1)/T0_Korrektur!K27) -> -999 | M27: =IF(K27="","",$K$3-K27) -> 0 | N27: =IF(M27="","",L27-K27+K$3-L$3) -> 0 | O27: =L27+K27-O$1 -> #DIV/0! | P27: =IF(T0_Korrektur!M27=-999,-999,T0_Korrektur!N27*ABS(T0_Korrektur!B27-T0_Korrektur!M$1)/T0_Korrektur!M27) -> -999 | Q27: =IF(T0_Korrektur!O27=-999,-999,T0_Korrektur!P27*ABS(T0_Korrektur!B27-T0_Korrektur!O$1)/T0_Korrektur!O27) -> -999 | R27: =IF(P27="","",$P$3-P27) -> 0 | S27: =IF(R27="","",Q27-P27+P$3-Q$3) -> 0 | T27: =Q27+P27-T$1 -> #DIV/0!
A28: 26 | B28: ='Picks importieren'!B29 -> 100 | D28: =T0_Korrektur!D28*ABS(T0_Korrektur!B28-T0_Korrektur!C$1)/T0_Korrektur!C28 -> 8.3211767 | E28: =T0_Korrektur!F28*ABS(T0_Korrektur!B28-T0_Korrektur!E$1)/T0_Korrektur!E28 -> 70.809258 | F28: =T0_Korrektur!H28*ABS(T0_Korrektur!B28-T0_Korrektur!G$1)/T0_Korrektur!G28 -> 73.42058 | G28: =E28+$F$50-$E$3 -> 69.696303 | H28: =$G$3-G28 -> 30.107345 | I28: =IF(H28="","",F28-E28+E$3-F$3) -> 97.108859 | J28: =F28+E28-J$1 -> 43.025272 | K28: =IF(T0_Korrektur!I28=-999,-999,T0_Korrektur!J28*ABS(T0_Korrektur!B28-T0_Korrektur!I$1)/T0_Korrektur!I28) -> -999 | L28: =IF(T0_Korrektur!K28=-999,-999,T0_Korrektur!L28*ABS(T0_Korrektur!B28-T0_Korrektur!K$1)/T0_Korrektur!K28) -> -999 | M28: =IF(K28="","",$K$3-K28) -> 0 | N28: =IF(M28="","",L28-K28+K$3-L$3) -> 0 | O28: =L28+K28-O$1 -> #DIV/0! | P28: =IF(T0_Korrektur!M28=-999,-999,T0_Korrektur!N28*ABS(T0_Korrektur!B28-T0_Korrektur!M$1)/T0_Korrektur!M28) -> -999 | Q28: =IF(T0_Korrektur!O28=-999,-999,T0_Korrektur!P28*ABS(T0_Korrektur!B28-T0_Korrektur!O$1)/T0_Korrektur!O28) -> -999 | R28: =IF(P28="","",$P$3-P28) -> 0 | S28: =IF(R28="","",Q28-P28+P$3-Q$3) -> 0 | T28: =Q28+P28-T$1 -> #DIV/0!
A29: 27 | B29: ='Picks importieren'!B30 -> 102.5 | D29: =T0_Korrektur!D29*ABS(T0_Korrektur!B29-T0_Korrektur!C$1)/T0_Korrektur!C29 -> 13.352767 | E29: =T0_Korrektur!F29*ABS(T0_Korrektur!B29-T0_Korrektur!E$1)/T0_Korrektur!E29 -> 70.451061 | F29: =T0_Korrektur!H29*ABS(T0_Korrektur!B29-T0_Korrektur!G$1)/T0_Korrektur!G29 -> 74.445262 | G29: =E29+$F$50-$E$3 -> 69.338107 | H29: =$G$3-G29 -> 30.465542 | I29: =IF(H29="","",F29-E29+E$3-F$3) -> 98.491737 | J29: =F29+E29-J$1 -> 43.691757 | K29: =IF(T0_Korrektur!I29=-999,-999,T0_Korrektur!J29*ABS(T0_Korrektur!B29-T0_Korrektur!I$1)/T0_Korrektur!I29) -> -999 | L29: =IF(T0_Korrektur!K29=-999,-999,T0_Korrektur!L29*ABS(T0_Korrektur!B29-T0_Korrektur!K$1)/T0_Korrektur!K29) -> -999 | M29: =IF(K29="","",$K$3-K29) -> 0 | N29: =IF(M29="","",L29-K29+K$3-L$3) -> 0 | O29: =L29+K29-O$1 -> #DIV/0! | P29: =IF(T0_Korrektur!M29=-999,-999,T0_Korrektur!N29*ABS(T0_Korrektur!B29-T0_Korrektur!M$1)/T0_Korrektur!M29) -> -999 | Q29: =IF(T0_Korrektur!O29=-999,-999,T0_Korrektur!P29*ABS(T0_Korrektur!B29-T0_Korrektur!O$1)/T0_Korrektur!O29) -> -999 | R29: =IF(P29="","",$P$3-P29) -> 0 | S29: =IF(R29="","",Q29-P29+P$3-Q$3) -> 0 | T29: =Q29+P29-T$1 -> #DIV/0!
A30: 28 | B30: ='Picks importieren'!B31 -> 105 | D30: =T0_Korrektur!D30*ABS(T0_Korrektur!B30-T0_Korrektur!C$1)/T0_Korrektur!C30 -> 17.353905 | E30: =T0_Korrektur!F30*ABS(T0_Korrektur!B30-T0_Korrektur!E$1)/T0_Korrektur!E30 -> 69.632997 | F30: =T0_Korrektur!H30*ABS(T0_Korrektur!B30-T0_Korrektur!G$1)/T0_Korrektur!G30 -> 75.341939 | G30: =E30+$F$50-$E$3 -> 68.520042 | H30: =$G$3-G30 -> 31.283606 | I30: =IF(H30="","",F30-E30+E$3-F$3) -> 100.20648 | J30: =F30+E30-J$1 -> 43.77037 | K30: =IF(T0_Korrektur!I30=-999,-999,T0_Korrektur!J30*ABS(T0_Korrektur!B30-T0_Korrektur!I$1)/T0_Korrektur!I30) -> -999 | L30: =IF(T0_Korrektur!K30=-999,-999,T0_Korrektur!L30*ABS(T0_Korrektur!B30-T0_Korrektur!K$1)/T0_Korrektur!K30) -> -999 | M30: =IF(K30="","",$K$3-K30) -> 0 | N30: =IF(M30="","",L30-K30+K$3-L$3) -> 0 | O30: =L30+K30-O$1 -> #DIV/0! | P30: =IF(T0_Korrektur!M30=-999,-999,T0_Korrektur!N30*ABS(T0_Korrektur!B30-T0_Korrektur!M$1)/T0_Korrektur!M30) -> -999 | Q30: =IF(T0_Korrektur!O30=-999,-999,T0_Korrektur!P30*ABS(T0_Korrektur!B30-T0_Korrektur!O$1)/T0_Korrektur!O30) -> -999 | R30: =IF(P30="","",$P$3-P30) -> 0 | S30: =IF(R30="","",Q30-P30+P$3-Q$3) -> 0 | T30: =Q30+P30-T$1 -> #DIV/0!
A31: 29 | B31: ='Picks importieren'!B32 -> 107.5 | D31: =T0_Korrektur!D31*ABS(T0_Korrektur!B31-T0_Korrektur!C$1)/T0_Korrektur!C31 -> 21.969583 | E31: =T0_Korrektur!F31*ABS(T0_Korrektur!B31-T0_Korrektur!E$1)/T0_Korrektur!E31 -> 68.61043 | F31: =T0_Korrektur!H31*ABS(T0_Korrektur!B31-T0_Korrektur!G$1)/T0_Korrektur!G31 -> 75.726462 | G31: =E31+$F$50-$E$3 -> 67.497476 | H31: =$G$3-G31 -> 32.306173 | I31: =IF(H31="","",F31-E31+E$3-F$3) -> 101.61357 | J31: =F31+E31-J$1 -> 43.132327 | K31: =IF(T0_Korrektur!I31=-999,-999,T0_Korrektur!J31*ABS(T0_Korrektur!B31-T0_Korrektur!I$1)/T0_Korrektur!I31) -> -999 | L31: =IF(T0_Korrektur!K31=-999,-999,T0_Korrektur!L31*ABS(T0_Korrektur!B31-T0_Korrektur!K$1)/T0_Korrektur!K31) -> -999 | M31: =IF(K31="","",$K$3-K31) -> 0 | N31: =IF(M31="","",L31-K31+K$3-L$3) -> 0 | O31: =L31+K31-O$1 -> #DIV/0! | P31: =IF(T0_Korrektur!M31=-999,-999,T0_Korrektur!N31*ABS(T0_Korrektur!B31-T0_Korrektur!M$1)/T0_Korrektur!M31) -> -999 | Q31: =IF(T0_Korrektur!O31=-999,-999,T0_Korrektur!P31*ABS(T0_Korrektur!B31-T0_Korrektur!O$1)/T0_Korrektur!O31) -> -999 | R31: =IF(P31="","",$P$3-P31) -> 0 | S31: =IF(R31="","",Q31-P31+P$3-Q$3) -> 0 | T31: =Q31+P31-T$1 -> #DIV/0!
A32: 30 | B32: ='Picks importieren'!B33 -> 112.5 | D32: =T0_Korrektur!D32*ABS(T0_Korrektur!B32-T0_Korrektur!C$1)/T0_Korrektur!C32 -> 29.62085 | E32: =T0_Korrektur!F32*ABS(T0_Korrektur!B32-T0_Korrektur!E$1)/T0_Korrektur!E32 -> 66.360821 | F32: =T0_Korrektur!H32*ABS(T0_Korrektur!B32-T0_Korrektur!G$1)/T0_Korrektur!G32 -> 76.584819 | G32: =E32+$F$50-$E$3 -> 65.247866 | H32: =$G$3-G32 -> 34.555782 | I32: =IF(H32="","",F32-E32+E$3-F$3) -> 104.72153 | J32: =F32+E32-J$1 -> 41.741075 | K32: =IF(T0_Korrektur!I32=-999,-999,T0_Korrektur!J32*ABS(T0_Korrektur!B32-T0_Korrektur!I$1)/T0_Korrektur!I32) -> -999 | L32: =IF(T0_Korrektur!K32=-999,-999,T0_Korrektur!L32*ABS(T0_Korrektur!B32-T0_Korrektur!K$1)/T0_Korrektur!K32) -> -999 | M32: =IF(K32="","",$K$3-K32) -> 0 | N32: =IF(M32="","",L32-K32+K$3-L$3) -> 0 | O32: =L32+K32-O$1 -> #DIV/0! | P32: =IF(T0_Korrektur!M32=-999,-999,T0_Korrektur!N32*ABS(T0_Korrektur!B32-T0_Korrektur!M$1)/T0_Korrektur!M32) -> -999 | Q32: =IF(T0_Korrektur!O32=-999,-999,T0_Korrektur!P32*ABS(T0_Korrektur!B32-T0_Korrektur!O$1)/T0_Korrektur!O32) -> -999 | R32: =IF(P32="","",$P$3-P32) -> 0 | S32: =IF(R32="","",Q32-P32+P$3-Q$3) -> 0 | T32: =Q32+P32-T$1 -> #DIV/0!
A33: 31 | B33: ='Picks importieren'!B34 -> 117.5 | D33: =T0_Korrektur!D33*ABS(T0_Korrektur!B33-T0_Korrektur!C$1)/T0_Korrektur!C33 -> 33.151684 | E33: =T0_Korrektur!F33*ABS(T0_Korrektur!B33-T0_Korrektur!E$1)/T0_Korrektur!E33 -> 63.906682 | F33: =T0_Korrektur!H33*ABS(T0_Korrektur!B33-T0_Korrektur!G$1)/T0_Korrektur!G33 -> 77.811947 | G33: =E33+$F$50-$E$3 -> 62.793727 | H33: =$G$3-G33 -> 37.009921 | I33: =IF(H33="","",F33-E33+E$3-F$3) -> 108.4028 | J33: =F33+E33-J$1 -> 40.514063 | K33: =IF(T0_Korrektur!I33=-999,-999,T0_Korrektur!J33*ABS(T0_Korrektur!B33-T0_Korrektur!I$1)/T0_Korrektur!I33) -> -999 | L33: =IF(T0_Korrektur!K33=-999,-999,T0_Korrektur!L33*ABS(T0_Korrektur!B33-T0_Korrektur!K$1)/T0_Korrektur!K33) -> -999 | M33: =IF(K33="","",$K$3-K33) -> 0 | N33: =IF(M33="","",L33-K33+K$3-L$3) -> 0 | O33: =L33+K33-O$1 -> #DIV/0! | P33: =IF(T0_Korrektur!M33=-999,-999,T0_Korrektur!N33*ABS(T0_Korrektur!B33-T0_Korrektur!M$1)/T0_Korrektur!M33) -> -999 | Q33: =IF(T0_Korrektur!O33=-999,-999,T0_Korrektur!P33*ABS(T0_Korrektur!B33-T0_Korrektur!O$1)/T0_Korrektur!O33) -> -999 | R33: =IF(P33="","",$P$3-P33) -> 0 | S33: =IF(R33="","",Q33-P33+P$3-Q$3) -> 0 | T33: =Q33+P33-T$1 -> #DIV/0!
